Workbook
Name avista: Sup!$D$2
Name b_1000: #REF!
Name b_10000: #REF!
Name b_100000: #REF!
Name b_10001: #REF!
Name b_100k: #REF!
Name b_100k: Sup!$L$2:$L$25
Name b_10k: #REF!
Name b_10k: Sup!$H$2:$H$15
Name b_1k: #REF!
Name b_1k: Sup!$E$2:$E$4
Name b_20000: #REF!
Name b_25001: #REF!
Name b_25k: #REF!
Name b_25k: Sup!$I$2:$I$18
Name b_3000: #REF!
Name b_3001: #REF!
Name b_3k: #REF!
Name b_3k: Sup!$F$2:$F$7
Name b_40000: #REF!
Name b_5000: #REF!
Name b_50001: #REF!
Name b_5001: #REF!
Name b_5001: #REF!
Name b_5001: Sup!$G$2:$G$12
Name b_50k: #REF!
Name b_50k: Sup!$J$2:$J$21
Name b_7500: #REF!
Name b_75000: #REF!
Name b_75001: #REF!
Name b_75k: #REF!
Name b_75k: Sup!$K$2:$K$22
Name cc_10k: Sup!$M$2:$M$7
Name ccr: #REF!
Name ccr: Sup!$M$2:$M$5
Name ccredito: #REF!
Name condpgto: #REF!
Name condpgto: #REF!
Name condpgto: Sup!$B$2:$B$4
Name formadepgto: #REF!
Name formadepgto: #REF!
Name formadepgto: Sup!$C$2:$C$3

Sheet Pedido
D1: Premium
C2: Vigência | D2: 46204
C3: Tabela | D3: FARMACIAS ESP.
C4: Valor total do pedido | D4: =SUMPRODUCT(K17:K307) -> 0
C5: Tipo de cliente | D5: Escolha o Tipo de cliente
C6: Região | D6: Escolha a Região | N6: v3
A8: BARRAS | B8: =SUMIFS($K$17:$K$292,$F$17:$F$292,$A8) -> 0
A9: CREATINAS | B9: =SUMIFS($K$17:$K$292,$F$17:$F$292,$A9) -> 0
A10: SACHES | B10: =SUMIFS($K$17:$K$292,$F$17:$F$292,$A10) -> 0
A11: SHAKES | B11: =SUMIFS($K$17:$K$292,$F$17:$F$292,$A11) -> 0
A12: VITAMINAS | B12: =SUMIFS($K$17:$K$292,$F$17:$F$292,$A12) -> 0
A14: Categoria | C14: Informações do Produto | H14: Dados Financeiros | K14: Dados do Pedido
B16: Cód, SKU | C16: Nome | D16: Sabor/Cor | E16: Embalagem | F16: Família | G16: Volume | H16: Sugerido | I16: Mkup | J16: Preço Unit. | K16: Preço | L16: Qtd. | M16: Cx.
B17: 520412007 | C17: Proteína Sabores (4 unid.) | D17: Banana | E17: Pote | F17: =_xlfn.XLOOKUP(B17,Planilha1!A:A,Planilha1!B:B) -> OUTROS | G17: 600g | H17: 219.9 | I17: =IFERROR(H17/J17,"") -> 1.6599985 | J17: 132.47 | K17: =L17*J17 -> 0 | M17: 4 | S17: 6 | T17: 8 | U17: 4
B18: 520412014 | C18: Proteína Sabores (4 unid.) | D18: Cacau | E18: Pote | F18: =_xlfn.XLOOKUP(B18,Planilha1!A:A,Planilha1!B:B) -> OUTROS | G18: 600g | H18: 219.9 | I18: =IFERROR(H18/J18,"") -> 1.6599985 | J18: 132.47 | K18: =L18*J18 -> 0 | M18: 4 | S18: =S17+6 -> 12 | T18: =T17+8 -> 16 | U18: =U17+4 -> 8
B19: 520412051 | C19: Proteína Sabores (4 unid.) | D19: Cookies | E19: Pote | F19: =_xlfn.XLOOKUP(B19,Planilha1!A:A,Planilha1!B:B) -> OUTROS | G19: 600g | H19: 219.9 | I19: =IFERROR(H19/J19,"") -> 1.6599985 | J19: 132.47 | K19: =L19*J19 -> 0 | M19: 4 | S19: =S18+6 -> 18 | T19: =T18+8 -> 24 | U19: =U18+4 -> 12
B20: 520412027 | C20: Proteína Sabores (4 unid.) | D20: Doce de Leite | E20: Pote | F20: =_xlfn.XLOOKUP(B20,Planilha1!A:A,Planilha1!B:B) -> OUTROS | G20: 600g | H20: 219.9 | I20: =IFERROR(H20/J20,"") -> 1.6599985 | J20: 132.47 | K20: =L20*J20 -> 0 | M20: 4 | S20: =S19+6 -> 24 | T20: =T19+8 -> 32 | U20: =U19+4 -> 16
B21: 520412039 | C21: Proteína Sabores (4 unid.) | D21: Morango | E21: Pote | F21: =_xlfn.XLOOKUP(B21,Planilha1!A:A,Planilha1!B:B) -> OUTROS | G21: 600g | H21: 219.9 | I21: =IFERROR(H21/J21,"") -> 1.6599985 | J21: 132.47 | K21: =L21*J21 -> 0 | M21: 4 | S21: =S20+6 -> 30 | T21: =T20+8 -> 40 | U21: =U20+4 -> 20
B22: 520412093 | C22: Proteína Sabores (4 unid.) | D22: Sem Sabor | E22: Pote | F22: =_xlfn.XLOOKUP(B22,Planilha1!A:A,Planilha1!B:B) -> OUTROS | G22: 600g | H22: 219.9 | I22: =IFERROR(H22/J22,"") -> 1.6599985 | J22: 132.47 | K22: =L22*J22 -> 0 | M22: 4 | S22: =S21+6 -> 36 | T22: =T21+8 -> 48 | U22: =U21+4 -> 24
B23: 520412079 | C23: Proteína Sabores (4 unid.) | D23: Salted Caramel | E23: Pote | F23: =_xlfn.XLOOKUP(B23,Planilha1!A:A,Planilha1!B:B) -> OUTROS | G23: 600g | H23: 219.9 | I23: =IFERROR(H23/J23,"") -> 1.6599985 | J23: 132.47 | K23: =L23*J23 -> 0 | M23: 4 | S23: =S22+6 -> 42 | T23: =T22+8 -> 56 | U23: =U22+4 -> 28
B24: 520349101 | C24: Display Barra Frutas (12 unid.) | D24: Bananinha com Paçoca | E24: Barra | F24: =_xlfn.XLOOKUP(B24,Planilha1!A:A,Planilha1!B:B) -> BARRAS | G24: 30g | H24: 9.9 | I24: =IFERROR(H24/J24,"") -> 1.5114504 | J24: 6.55 | K24: =L24*J24 -> 0 | M24: 12 | S24: =#REF!+6 -> #REF! | T24: =#REF!+8 -> #REF! | U24: =#REF!+4 -> #REF!
B25: 520349100 | C25: Display Barra Frutas (12 unid.) | D25: Berries | E25: Barra | F25: =_xlfn.XLOOKUP(B25,Planilha1!A:A,Planilha1!B:B) -> BARRAS | G25: 30g | H25: 9.9 | I25: =IFERROR(H25/J25,"") -> 1.5114504 | J25: 6.55 | K25: =L25*J25 -> 0 | M25: 12 | S25: =S24+6 -> #REF! | T25: =T24+8 -> #REF! | U25: =U24+4 -> #REF!
B26: 520349080 | C26: Display Barra de Proteína (12 unid.) | D26: Chocolate Belga | E26: Barra | F26: =_xlfn.XLOOKUP(B26,Planilha1!A:A,Planilha1!B:B) -> BARRAS | G26: 45g | H26: 11.9 | I26: =IFERROR(H26/J26,"") -> 1.5657895 | J26: 7.6 | K26: =L26*J26 -> 0 | M26: 12 | S26: =S25+6 -> #REF! | T26: =T25+8 -> #REF! | U26: =U25+4 -> #REF!
B27: 520349051 | C27: Display Barra de Proteína (12 unid.) | D27: Cookies & Cream | E27: Barra | F27: =_xlfn.XLOOKUP(B27,Planilha1!A:A,Planilha1!B:B) -> BARRAS | G27: 45g | H27: 11.9 | I27: =IFERROR(H27/J27,"") -> 1.5657895 | J27: 7.6 | K27: =L27*J27 -> 0 | M27: 12 | S27: =S26+6 -> #REF! | T27: =T26+8 -> #REF! | U27: =U26+4 -> #REF!
B28: 520349027 | C28: Display Barra de Proteína (12 unid.) | D28: Doce de Leite | E28: Barra | F28: =_xlfn.XLOOKUP(B28,Planilha1!A:A,Planilha1!B:B) -> BARRAS | G28: 45g | H28: 11.9 | I28: =IFERROR(H28/J28,"") -> 1.5657895 | J28: 7.6 | K28: =L28*J28 -> 0 | M28: 12 | S28: =S27+6 -> #REF! | T28: =T27+8 -> #REF! | U28: =U27+4 -> #REF!
B29: 520349081 | C29: Display Barra de Proteína (12 unid.) | D29: Morango & Chocolate Branco | E29: Barra | F29: =_xlfn.XLOOKUP(B29,Planilha1!A:A,Planilha1!B:B) -> BARRAS | G29: 45g | H29: 11.9 | I29: =IFERROR(H29/J29,"") -> 1.5657895 | J29: 7.6 | K29: =L29*J29 -> 0 | M29: 12 | S29: =S28+6 -> #REF! | T29: =T28+8 -> #REF! | U29: =U28+4 -> #REF!
B30: 520349083 | C30: Display Barra de Proteína (12 unid.) | D30: Pistache | E30: Barra | F30: =_xlfn.XLOOKUP(B30,Planilha1!A:A,Planilha1!B:B) -> BARRAS | G30: 45g | H30: 11.9 | I30: =IFERROR(H30/J30,"") -> 1.5657895 | J30: 7.6 | K30: =L30*J30 -> 0 | M30: 12 | S30: =S29+6 -> #REF! | T30: =T29+8 -> #REF! | U30: =U29+4 -> #REF!
B31: 520349079 | C31: Display Barra de Proteína (12 unid.) | D31: Salted Caramel | E31: Barra | F31: =_xlfn.XLOOKUP(B31,Planilha1!A:A,Planilha1!B:B) -> BARRAS | G31: 45g | H31: 11.9 | I31: =IFERROR(H31/J31,"") -> 1.5657895 | J31: 7.6 | K31: =L31*J31 -> 0 | M31: 12 | S31: =S30+6 -> #REF! | T31: =T30+8 -> #REF! | U31: =U30+4 -> #REF!
B32: 520204080 | C32: Pasta Amendoim | D32: Chocolate Belga | E32: Pote | F32: =_xlfn.XLOOKUP(B32,Planilha1!A:A,Planilha1!B:B) -> OUTROS | G32: 300g | H32: 33.9 | I32: =IFERROR(H32/J32,"") -> 1.6593245 | J32: 20.43 | K32: =L32*J32 -> 0 | M32: 6 | S32: =#REF!+6 -> #REF! | T32: =#REF!+8 -> #REF! | U32: =#REF!+4 -> #REF!
B33: 520204078 | C33: Pasta Amendoim | D33: Integral | E33: Pote | F33: =_xlfn.XLOOKUP(B33,Planilha1!A:A,Planilha1!B:B) -> OUTROS | G33: 300g | H33: 33.9 | I33: =IFERROR(H33/J33,"") -> 1.6593245 | J33: 20.43 | K33: =L33*J33 -> 0 | M33: 6 | S33: =#REF!+6 -> #REF! | T33: =#REF!+8 -> #REF! | U33: =#REF!+4 -> #REF!
B34: 520204079 | C34: Pasta Amendoim | D34: Salted Caramel | E34: Pote | F34: =_xlfn.XLOOKUP(B34,Planilha1!A:A,Planilha1!B:B) -> OUTROS | G34: 300g | H34: 33.9 | I34: =IFERROR(H34/J34,"") -> 1.6593245 | J34: 20.43 | K34: =L34*J34 -> 0 | M34: 6 | S34: =#REF!+6 -> #REF! | T34: =#REF!+8 -> #REF! | U34: =#REF!+4 -> #REF!
B35: 521304083 | C35: Pasta de Pistache | D35: - | E35: Pote | F35: =_xlfn.XLOOKUP(B35,Planilha1!A:A,Planilha1!B:B) -> OUTROS | G35: 300g | H35: 79.9 | I35: =IFERROR(H35/J35,"") -> 1.6597424 | J35: 48.14 | K35: =L35*J35 -> 0 | M35: 6 | S35: =#REF!+6 -> #REF! | T35: =#REF!+8 -> #REF! | U35: =#REF!+4 -> #REF!
B36: 521304095 | C36: Pasta de Avelã | D36: - | E36: Pote | F36: =_xlfn.XLOOKUP(B36,Planilha1!A:A,Planilha1!B:B) -> OUTROS | G36: 300g | H36: 79.9 | I36: =IFERROR(H36/J36,"") -> 1.6597424 | J36: 48.14 | K36: =L36*J36 -> 0 | M36: 6 | S36: =S35+6 -> #REF! | T36: =T35+8 -> #REF! | U36: =U35+4 -> #REF!
B37: 521304097 | C37: Pasta de Macadâmia | D37: - | E37: Pote | F37: =_xlfn.XLOOKUP(B37,Planilha1!A:A,Planilha1!B:B) -> OUTROS | G37: 300g | H37: 79.9 | I37: =IFERROR(H37/J37,"") -> 1.6597424 | J37: 48.14 | K37: =L37*J37 -> 0 | M37: 6 | S37: =S36+6 -> #REF! | T37: =T36+8 -> #REF! | U37: =U36+4 -> #REF!
B38: 520104088 | C38: Pasta Castanha | D38: Cacau Nibs | E38: Pote | F38: =_xlfn.XLOOKUP(B38,Planilha1!A:A,Planilha1!B:B) -> OUTROS | G38: 300g | H38: 37.9 | I38: =IFERROR(H38/J38,"") -> 1.2864902 | J38: 29.46 | K38: =L38*J38 -> 0 | M38: 6 | S38: =#REF!+6 -> #REF! | T38: =#REF!+8 -> #REF! | U38: =#REF!+4 -> #REF!
B39: 520104080 | C39: Pasta Castanha | D39: Chocolate Belga | E39: Pote | F39: =_xlfn.XLOOKUP(B39,Planilha1!A:A,Planilha1!B:B) -> OUTROS | G39: 300g | H39: 37.9 | I39: =IFERROR(H39/J39,"") -> 1.2864902 | J39: 29.46 | K39: =L39*J39 -> 0 | M39: 6 | S39: =#REF!+6 -> #REF! | T39: =#REF!+8 -> #REF! | U39: =#REF!+4 -> #REF!
B40: 520104051 | C40: Pasta Castanha | D40: Cookies 'N' Cream | E40: Pote | F40: =_xlfn.XLOOKUP(B40,Planilha1!A:A,Planilha1!B:B) -> OUTROS | G40: 300g | H40: 37.9 | I40: =IFERROR(H40/J40,"") -> 1.2864902 | J40: 29.46 | K40: =L40*J40 -> 0 | M40: 6 | S40: =S39+6 -> #REF! | T40: =T39+8 -> #REF! | U40: =U39+4 -> #REF!
B41: 520104027 | C41: Pasta Castanha | D41: Doce de Leite | E41: Pote | F41: =_xlfn.XLOOKUP(B41,Planilha1!A:A,Planilha1!B:B) -> OUTROS | G41: 300g | H41: 37.9 | I41: =IFERROR(H41/J41,"") -> 1.2864902 | J41: 29.46 | K41: =L41*J41 -> 0 | M41: 6 | S41: =S40+6 -> #REF! | T41: =T40+8 -> #REF! | U41: =U40+4 -> #REF!
B42: 520104078 | C42: Pasta Castanha | D42: Integral | E42: Pote | F42: =_xlfn.XLOOKUP(B42,Planilha1!A:A,Planilha1!B:B) -> OUTROS | G42: 300g | H42: 37.9 | I42: =IFERROR(H42/J42,"") -> 1.2864902 | J42: 29.46 | K42: =L42*J42 -> 0 | M42: 6 | S42: =S41+6 -> #REF! | T42: =T41+8 -> #REF! | U42: =U41+4 -> #REF!
B43: 520104094 | C43: Pasta Castanha | D43: Morango com Choc Branco | E43: Pote | F43: =_xlfn.XLOOKUP(B43,Planilha1!A:A,Planilha1!B:B) -> OUTROS | G43: 300g | H43: 37.9 | I43: =IFERROR(H43/J43,"") -> 1.2864902 | J43: 29.46 | K43: =L43*J43 -> 0 | M43: 6 | S43: =#REF!+6 -> #REF! | T43: =#REF!+8 -> #REF! | U43: =#REF!+4 -> #REF!
...

Sheet Planilha2
A1: 450327107 | B1: Collagen Advanced (10 unidades) | C1: Tangerina e Hibisco | D1: Sachê
A2: 460469001 | B2: Protein Brownie | D2: Pouch
A3: 430213134 | B3: Fresh Whey | C3: Fior Di Latte e Especiarias | D3: Pote
A4: 430213133 | B4: Fresh Whey | C4: Fior Di Latte e Limão Siciliano | D4: Pote
A5: 411127116 | B5: Whey Protein Isolado (10 und.) | C5: Caramelo Salgado | D5: Sachê

Sheet Planilha1
A1: codigo_produto | B1: grupo_remuneracao_variavel
A2: 520349101 | B2: BARRAS
A3: 520349100 | B3: BARRAS
A4: 520349079 | B4: BARRAS
A5: 520349051 | B5: BARRAS
A6: 520349027 | B6: BARRAS
A7: 520349080 | B7: BARRAS
A8: 520349083 | B8: BARRAS
A9: 520349081 | B9: BARRAS
A10: 510339080 | B10: BARRAS
A11: 510339081 | B11: BARRAS
A12: 510339079 | B12: BARRAS
A13: 510339023 | B13: BARRAS
... A650: 433809040 | B650: OUTROS

Sheet Cálculo
E1: Vendedor | CC1: Escolha o Tipo de cliente | CE1: Escolha a Região
D2: Vigência | E2: 45383 | CC2: BODYSHOP | CD2: 1 | CE2: Norte/Nordeste | CF2: 1
D3: Versão | E3: Vendedor V1 | CC3: CANAL VERDE | CD3: 1 | CE3: Centro Oeste | CF3: 1
D4: Valor total do pedido | E4: =SUMPRODUCT(U61:U368,X61:X368)+SUMPRODUCT(U61:U368,W61:W368) -> 0 | CC4: OUTROS ESPECIALIZADO | CD4: 1 | CE4: Sul/Sudeste | CF4: 1
D5: ID do Pedido | CC5: E-COMMERCE ESPECIALIZADO | CD5: 1 | CE5: Contas Nacionais | CF5: 1
D6: ID do Cliente | BF6: v3
D7: ID do Vendedor | F7: COMBOS NO PEDIDO | G7: =Pedido!G7 -> 0 | CD7: =IFERROR(VLOOKUP(Pedido!D5,Cálculo!CC1:CD5,2,0),0) -> 0 | CF7: =IFERROR(VLOOKUP(Pedido!D6,Cálculo!CE1:CF5,2,0),0) -> 0
D8: Frete | Q8: =TODAY() -> 46203 | BG8: 0
D9: Condição de Pagamento | F9: CASHBACK | Q9: 45327 | AR9: DUX | AX9: =SUMPRODUCT(U61:U350,W61:W350) -> 0 | BG9: Coqueteleiras | CD9: 1 | CE9: 1
D10: Desconto à vista | E10: 0.05
D11: Desconto Cartão de Crédito | E11: =IFERROR(VLOOKUP(E15,Sup!M:O,3,0),0) -> 0
D12: Desconto Frete FOB | E12: 0.02
D13: Multiplicador | E13: =IF(E9="À vista",1-E10,IF(AND(E9="A prazo",E15=15),0.96,IF(AND(E9="A prazo",E15=30),0.985,IF(AND(E9="A prazo",E15="15/30"),0.985,IF(AND(E9="A prazo",E15="14/21/28/35"),0.985,IF(AND(E9="A prazo",E14="C. Crédito",E15<=4),1-E11,1))))))*IF(E8="FOB",1-E12,1) -> 1
D14: Forma de Pagamento | Q14: =Q9-Q8 -> -876 | AR14: Eat Clean | AX14: =SUMPRODUCT(U28:U60,W28:W60) -> 0 | BG14: 900 | BH14: =SUMIF(G189:G192,BG14,W189:W192)+SUMIF(G223:G234,BG14,W223:W234)+SUMIF(G259:G266,BG14,W259:W266) -> 0 | BI14: =BH14/2 -> 0 | BJ14: =ROUNDDOWN(BI14,0) -> 0
A15: =IF(SUM(Pedido!L170:L176)=0,0,ISEVEN(SUM(Pedido!L170:L176))) -> 0 | D15: Prazo de Pagamento | Q15: =SUM(W106:W109) -> 0 | AR15: Total | AX15: =SUM(AX9:AX14) -> 0 | BG15: 1800 | BH15: =SUMIF(G235:G244,BG15,W235:W244)+SUMIF(G268:G275,BG15,W268:W275) -> 0 | BJ15: =BH15 -> 0 | BK15: NOVO/REATIVAÇÃO
D16: Margem Bruta Original (%) | E16: =AF373 -> 0
D17: Margem Bruta (%) | E17: =AT373 -> 0
D18: Resultado Bruto (R$) | E18: =E4*E17 -> 0
D22: Verba do pedido | E22: =BB372-AD373+BC372+Cálculo!CD24 -> 0
D23: Status | E23: =IF(SUM(Z:Z)<0,"Pedido Reprovado",IF(E4>0,IF(E22>=0,"Pedido Aprovado","Pedido Reprovado"),)) -> 0 | BG23: =IF(BH23=0,1,BH23) -> 1 | BH23: =ABS(IF(W73="",AH373,(U73*W73)-AH373)) -> 0
BI24: =IF(W73="",0,IF(BG23=1,BG23,(U73*W73)/BG23)) -> 0 | CC24: Bônus DZ13
A25: Categoria | D25: Informações do Produto | I25: Dados Financeiros | M25: Desconto por volume | T25: Dados do Pedido | AJ25: 0.1 | AK25: 0.085 | AL25: 0.02
F26: Embalagem | M26: 1800 | N26: 1800 | O26: 1800 | P26: 1800 | Q26: 30000 | R26: 45000 | S26: 10000000 | BZ26: Preço mínimo final negociável
B27: Cód. SKU | C27: Cód. Prod. | D27: Nome | E27: Sabor/Cor | F27: Modelo | G27: Volume | I27: Sugerido | J27: Mkup | K27: Desc | L27: Preço | M27: 1500 | N27: 1800 | O27: 1800 | P27: 1800 | Q27: 60 | R27: 120 | S27: 200 | T27: Preço | U27: Preço Efet. | V27: Negociação | W27: Qtd. | X27: Bonif. | Y27: Preço | Z27: ✓ | AA27: Rec. Máx. | AB27: Rec. Orig. | AC27: Dif. | AD27: Verba | AE27: Custo Orig. | AF27: MB Orig. | AG27: Total Sug. | AH27: Receita | AI27: Custo | AJ27: Imposto | AK27: Logistica | AL27: Comissão | AM27: Deduções | AN27: Rec. Líq. | AO27: Lucro Bruto | AP27: MB | AQ27: Preço efet. Mín | AR27: Cx. | AS27: MB | AT27: MB | AU27: MC | AW27: Classe | AX27: Classe | AY27: Peso | AZ27: Verba classif | BA27: Verba preço | BB27: Verba final | BC27: Subtração | BD27: Preço ref | BE27: Dif real
B28: 14842467944 | C28: Proteína Sabores | D28: Proteína Sabores | E28: Cacau | F28: Pote | G28: 600g | H28: 157.77 | I28: 648.4896 | J28: =IFERROR(IF(T28<>"",I28/T28,IF(AND(Y28="",V28=""),"",IF(V28="",I28/Y28,I28/V28))),"") | K28: =IF(Y28="","",IFERROR(1-(Y28/I28),0)) | L28: 391.6 | M28: =P28 -> 360.272 | N28: =P28 -> 360.272 | O28: =P28 -> 360.272 | P28: 360.272 | Q28: 360.272 | R28: 360.272 | S28: 360.272 | T28: =IF(V28>0,V28,IFERROR(IF(AND(W28<>"",X28<>""),AH28/W28,Y28),"")) | U28: =IFERROR((T28*W28)/(W28+X28),"") | Y28: =IF(AND(W28="",X28=""),"",$E$13*IF(V28<>"",V28,IF(SUMIF($C:$C,C28,$W:$W)>=$S$27,S28,IF(OR($AA$373>=$R$26,SUMIF($C:$C,C28,$W:$W)>=$R$27),R28,IF(OR($AA$373>=$Q$26,SUMIF($C:$C,C28,$W:$W)>=$Q$27),Q28,IF(OR($AA$373>=$P$26,SUMIF($C:$C,C28,$W:$W)>=$P$27),P28,IF(OR($AA$373>=$O$26,SUMIF($C:$C,C28,$W:$W)>=$O$27),O28,IF(OR($AA$373>=$N$26,SUMIF($C:$C,C28,$W:$W)>=$N$27),N28,IF($AA$373>=$M$26,M28,L28))))))))) | Z28: =IF(X28>W28,-1,IF(W28=0,0,IF(U28<(H28/0.75),-1,IF(W28<=3,0,0.0001)))) -> 0 | AA28: =IFERROR(L28*W28,0) -> 0 | AB28: =IFERROR(IF(OR($AA$373>=$S$26,SUMIF($C:$C,C28,$W:$W)>=$S$27),S28,IF(OR($AA$373>=$R$26,SUMIF($C:$C,C28,$W:$W)>=$R$27),R28,IF(OR($AA$373>=$Q$26,SUMIF($C:$C,C28,$W:$W)>=$Q$27),Q28,IF(OR($AA$373>=$P$26,SUMIF($C:$C,C28,$W:$W)>=$P$27),P28,IF(OR($AA$373>=$O$26,SUMIF($C:$C,C28,$W:$W)>=$O$27),O28,IF(OR($AA$373>=$N$26,SUMIF($C:$C,C28,$W:$W)>=$N$27),N28,IF($AA$373>=$M$26,M28,L28)))))))*W28,0) -> 0 | AC28: =IFERROR(IF(V28="",0,(IF(AND(W28="",X28=""),"",IF(OR($AA$373>=$S$26,SUMIF($C:$C,C28,$W:$W)>=$S$27),S28*$E$13,IF(OR($AA$373>=$R$26,SUMIF($C:$C,C28,$W:$W)>=$R$27),R28*$E$13,IF(OR($AA$373>=$Q$26,SUMIF($C:$C,C28,$W:$W)>=$Q$27),Q28*$E$13,IF(OR($AA$373>=$P$26,SUMIF($C:$C,C28,$W:$W)>=$P$27),P28*$E$13,IF(OR($AA$373>=$O$26,SUMIF($C:$C,C28,$W:$W)>=$O$27),O28*$E$13,IF(OR($AA$373>=$N$26,SUMIF($C:$C,C28,$W:$W)>=$N$27),N28*$E$13,IF($AA$373>=$M$26,M28*$E$13,L28))))))))-V28)*W28),0) -> 0 | AD28: =IFERROR(X28*T28,0) -> 0 | AE28: =IFERROR(W28*H28,0) -> 0 | AF28: =IFERROR(1-(AE28/AB28),0) -> 0 | AG28: =IFERROR(SUM(W28:X28)*I28,0) -> 0 | AH28: =IFERROR(IF(V28>0,V28*W28,(Y28*W28)),0) -> 0 | AI28: =IFERROR(SUM(W28)*H28,0) -> 0 | AJ28: =AH28*$AJ$25 -> 0 | AK28: =AH28*AK$25 -> 0 | AL28: =AH28*AL$25 -> 0 | AM28: =SUM(AJ28:AL28) -> 0 | AN28: =AH28-AM28 -> 0 | AO28: =AN28-AI28 -> 0 | AP28: =IFERROR(IF(V28<>"",1-(H28/V28),IF(Y28<>"",1-(H28/Y28),1-(H28/L28))),0) -> 0.5971144 | AQ28: =H28/0.75 -> 210.36 | AR28: 4 | AS28: =(AP28-MIN($AP$65:$AP$368))/(MAX($AP$65:$AP$368)-MIN($AP$65:$AP$368))*100 -> 59.71144 | AT28: =IFERROR(1-(AI28/AH28),0) -> 0 | AU28: =IFERROR(AO28/AH28,0) -> 0 | AW28: =VLOOKUP(AX28,Sup!#REF!,8,0) -> #REF! | AX28: Premium | AY28: 0 | BC28: =IF(BE28<0,BE28,0) -> 0 | BD28: =IFERROR(IF(AND(W28="",X28=""),"",IF(OR($AA$373>=$S$26,SUMIF($C:$C,C28,$W:$W)>=$S$27),S28,IF(OR($AA$373>=$R$26,SUMIF($C:$C,C28,$W:$W)>=$R$27),R28,IF(OR($AA$373>=$Q$26,SUMIF($C:$C,C28,$W:$W)>=$Q$27),Q28,IF(OR($AA$373>=$P$26,SUMIF($C:$C,C28,$W:$W)>=$P$27),P28,IF(OR($AA$373>=$O$26,SUMIF($C:$C,C28,$W:$W)>=$O$27),O28,IF(OR($AA$373>=$N$26,SUMIF($C:$C,C28,$W:$W)>=$N$27),N28,IF($AA$373>=$M$26,M28,L28)))))))*$E$13),0) | BE28: =IF(V28="",0,(V28*W28)-(BD28*W28)) -> 0 | BM28: =#REF!+24 -> #REF! | BW28: EAT CLEAN | BX28: =IFERROR(W28*U28,0) -> 0 | BY28: =VLOOKUP(B28,#REF!,13,0) -> #REF! | BZ28: 322 | CA28: =VLOOKUP(B28,Pedido!$B$16:$L$292,22,0) -> #N/A | CD28: 12 | CE28: =CD28/12 -> 1 | CF28: =CONCATENATE(CD28,CE28) -> 121 | CG28: válido
B29: 16041273496 | C29: Proteína Sabores | D29: Proteína Sabores | E29: Cookies | F29: Pote | G29: 600g | H29: 175.97 | I29: 648.4896 | J29: =IFERROR(IF(T29<>"",I29/T29,IF(AND(Y29="",V29=""),"",IF(V29="",I29/Y29,I29/V29))),"") | K29: =IF(Y29="","",IFERROR(1-(Y29/I29),0)) | L29: 391.6 | M29: =P29 -> 360.272 | N29: =P29 -> 360.272 | O29: =P29 -> 360.272 | P29: 360.272 | Q29: 360.272 | R29: 360.272 | S29: 360.272 | T29: =IF(V29>0,V29,IFERROR(IF(AND(W29<>"",X29<>""),AH29/W29,Y29),"")) | U29: =IFERROR((T29*W29)/(W29+X29),"") | Y29: =IF(AND(W29="",X29=""),"",$E$13*IF(V29<>"",V29,IF(SUMIF($C:$C,C29,$W:$W)>=$S$27,S29,IF(OR($AA$373>=$R$26,SUMIF($C:$C,C29,$W:$W)>=$R$27),R29,IF(OR($AA$373>=$Q$26,SUMIF($C:$C,C29,$W:$W)>=$Q$27),Q29,IF(OR($AA$373>=$P$26,SUMIF($C:$C,C29,$W:$W)>=$P$27),P29,IF(OR($AA$373>=$O$26,SUMIF($C:$C,C29,$W:$W)>=$O$27),O29,IF(OR($AA$373>=$N$26,SUMIF($C:$C,C29,$W:$W)>=$N$27),N29,IF($AA$373>=$M$26,M29,L29))))))))) | Z29: =IF(X29>W29,-1,IF(W29=0,0,IF(U29<(H29/0.75),-1,IF(W29<=3,0,0.0001)))) -> 0 | AA29: =IFERROR(L29*W29,0) -> 0 | AB29: =IFERROR(IF(OR($AA$373>=$S$26,SUMIF($C:$C,C29,$W:$W)>=$S$27),S29,IF(OR($AA$373>=$R$26,SUMIF($C:$C,C29,$W:$W)>=$R$27),R29,IF(OR($AA$373>=$Q$26,SUMIF($C:$C,C29,$W:$W)>=$Q$27),Q29,IF(OR($AA$373>=$P$26,SUMIF($C:$C,C29,$W:$W)>=$P$27),P29,IF(OR($AA$373>=$O$26,SUMIF($C:$C,C29,$W:$W)>=$O$27),O29,IF(OR($AA$373>=$N$26,SUMIF($C:$C,C29,$W:$W)>=$N$27),N29,IF($AA$373>=$M$26,M29,L29)))))))*W29,0) -> 0 | AC29: =IFERROR(IF(V29="",0,(IF(AND(W29="",X29=""),"",IF(OR($AA$373>=$S$26,SUMIF($C:$C,C29,$W:$W)>=$S$27),S29*$E$13,IF(OR($AA$373>=$R$26,SUMIF($C:$C,C29,$W:$W)>=$R$27),R29*$E$13,IF(OR($AA$373>=$Q$26,SUMIF($C:$C,C29,$W:$W)>=$Q$27),Q29*$E$13,IF(OR($AA$373>=$P$26,SUMIF($C:$C,C29,$W:$W)>=$P$27),P29*$E$13,IF(OR($AA$373>=$O$26,SUMIF($C:$C,C29,$W:$W)>=$O$27),O29*$E$13,IF(OR($AA$373>=$N$26,SUMIF($C:$C,C29,$W:$W)>=$N$27),N29*$E$13,IF($AA$373>=$M$26,M29*$E$13,L29))))))))-V29)*W29),0) -> 0 | AD29: =IFERROR(X29*T29,0) -> 0 | AE29: =IFERROR(W29*H29,0) -> 0 | AF29: =IFERROR(1-(AE29/AB29),0) -> 0 | AG29: =IFERROR(SUM(W29:X29)*I29,0) -> 0 | AH29: =IFERROR(IF(V29>0,V29*W29,(Y29*W29)),0) -> 0 | AI29: =IFERROR(SUM(W29)*H29,0) -> 0 | AJ29: =AH29*$AJ$25 -> 0 | AK29: =AH29*AK$25 -> 0 | AL29: =AH29*AL$25 -> 0 | AM29: =SUM(AJ29:AL29) -> 0 | AN29: =AH29-AM29 -> 0 | AO29: =AN29-AI29 -> 0 | AP29: =IFERROR(IF(V29<>"",1-(H29/V29),IF(Y29<>"",1-(H29/Y29),1-(H29/L29))),0) -> 0.55063841 | AQ29: =H29/0.75 -> 234.62667 | AR29: 4 | AS29: =(AP29-MIN($AP$65:$AP$368))/(MAX($AP$65:$AP$368)-MIN($AP$65:$AP$368))*100 -> 55.063841 | AT29: =IFERROR(1-(AI29/AH29),0) -> 0 | AU29: =IFERROR(AO29/AH29,0) -> 0 | AW29: =VLOOKUP(AX29,Sup!#REF!,8,0) -> #REF! | AX29: Premium | AY29: 0 | BC29: =IF(BE29<0,BE29,0) -> 0 | BD29: =IFERROR(IF(AND(W29="",X29=""),"",IF(OR($AA$373>=$S$26,SUMIF($C:$C,C29,$W:$W)>=$S$27),S29,IF(OR($AA$373>=$R$26,SUMIF($C:$C,C29,$W:$W)>=$R$27),R29,IF(OR($AA$373>=$Q$26,SUMIF($C:$C,C29,$W:$W)>=$Q$27),Q29,IF(OR($AA$373>=$P$26,SUMIF($C:$C,C29,$W:$W)>=$P$27),P29,IF(OR($AA$373>=$O$26,SUMIF($C:$C,C29,$W:$W)>=$O$27),O29,IF(OR($AA$373>=$N$26,SUMIF($C:$C,C29,$W:$W)>=$N$27),N29,IF($AA$373>=$M$26,M29,L29)))))))*$E$13),0) | BE29: =IF(V29="",0,(V29*W29)-(BD29*W29)) -> 0 | BM29: =BM28+24 -> #REF! | BW29: EAT CLEAN | BX29: =IFERROR(W29*U29,0) -> 0 | BY29: =VLOOKUP(B29,#REF!,13,0) -> #REF! | BZ29: 322 | CA29: =VLOOKUP(B29,Pedido!$B$16:$L$292,22,0) -> #N/A | CD29: =CD28+12 -> 24 | CE29: =CD29/12 -> 2 | CF29: =CONCATENATE(CD29,CE29) -> 242 | CG29: válido
B30: 520412027 | C30: Proteína Sabores | D30: Proteína Sabores | E30: Doce de Leite | F30: Pote | G30: 600g | H30: 175.97 | I30: 648.4896 | J30: =IFERROR(IF(T30<>"",I30/T30,IF(AND(Y30="",V30=""),"",IF(V30="",I30/Y30,I30/V30))),"") | K30: =IF(Y30="","",IFERROR(1-(Y30/I30),0)) | L30: 391.6 | M30: =P30 -> 360.272 | N30: =P30 -> 360.272 | O30: =P30 -> 360.272 | P30: 360.272 | Q30: 360.272 | R30: 360.272 | S30: 360.272 | T30: =IF(V30>0,V30,IFERROR(IF(AND(W30<>"",X30<>""),AH30/W30,Y30),"")) | U30: =IFERROR((T30*W30)/(W30+X30),"") | Y30: =IF(AND(W30="",X30=""),"",$E$13*IF(V30<>"",V30,IF(SUMIF($C:$C,C30,$W:$W)>=$S$27,S30,IF(OR($AA$373>=$R$26,SUMIF($C:$C,C30,$W:$W)>=$R$27),R30,IF(OR($AA$373>=$Q$26,SUMIF($C:$C,C30,$W:$W)>=$Q$27),Q30,IF(OR($AA$373>=$P$26,SUMIF($C:$C,C30,$W:$W)>=$P$27),P30,IF(OR($AA$373>=$O$26,SUMIF($C:$C,C30,$W:$W)>=$O$27),O30,IF(OR($AA$373>=$N$26,SUMIF($C:$C,C30,$W:$W)>=$N$27),N30,IF($AA$373>=$M$26,M30,L30))))))))) | Z30: =IF(X30>W30,-1,IF(W30=0,0,IF(U30<(H30/0.75),-1,IF(W30<=3,0,0.0001)))) -> 0 | AA30: =IFERROR(L30*W30,0) -> 0 | AB30: =IFERROR(IF(OR($AA$373>=$S$26,SUMIF($C:$C,C30,$W:$W)>=$S$27),S30,IF(OR($AA$373>=$R$26,SUMIF($C:$C,C30,$W:$W)>=$R$27),R30,IF(OR($AA$373>=$Q$26,SUMIF($C:$C,C30,$W:$W)>=$Q$27),Q30,IF(OR($AA$373>=$P$26,SUMIF($C:$C,C30,$W:$W)>=$P$27),P30,IF(OR($AA$373>=$O$26,SUMIF($C:$C,C30,$W:$W)>=$O$27),O30,IF(OR($AA$373>=$N$26,SUMIF($C:$C,C30,$W:$W)>=$N$27),N30,IF($AA$373>=$M$26,M30,L30)))))))*W30,0) -> 0 | AC30: =IFERROR(IF(V30="",0,(IF(AND(W30="",X30=""),"",IF(OR($AA$373>=$S$26,SUMIF($C:$C,C30,$W:$W)>=$S$27),S30*$E$13,IF(OR($AA$373>=$R$26,SUMIF($C:$C,C30,$W:$W)>=$R$27),R30*$E$13,IF(OR($AA$373>=$Q$26,SUMIF($C:$C,C30,$W:$W)>=$Q$27),Q30*$E$13,IF(OR($AA$373>=$P$26,SUMIF($C:$C,C30,$W:$W)>=$P$27),P30*$E$13,IF(OR($AA$373>=$O$26,SUMIF($C:$C,C30,$W:$W)>=$O$27),O30*$E$13,IF(OR($AA$373>=$N$26,SUMIF($C:$C,C30,$W:$W)>=$N$27),N30*$E$13,IF($AA$373>=$M$26,M30*$E$13,L30))))))))-V30)*W30),0) -> 0 | AD30: =IFERROR(X30*T30,0) -> 0 | AE30: =IFERROR(W30*H30,0) -> 0 | AF30: =IFERROR(1-(AE30/AB30),0) -> 0 | AG30: =IFERROR(SUM(W30:X30)*I30,0) -> 0 | AH30: =IFERROR(IF(V30>0,V30*W30,(Y30*W30)),0) -> 0 | AI30: =IFERROR(SUM(W30)*H30,0) -> 0 | AJ30: =AH30*$AJ$25 -> 0 | AK30: =AH30*AK$25 -> 0 | AL30: =AH30*AL$25 -> 0 | AM30: =SUM(AJ30:AL30) -> 0 | AN30: =AH30-AM30 -> 0 | AO30: =AN30-AI30 -> 0 | AP30: =IFERROR(IF(V30<>"",1-(H30/V30),IF(Y30<>"",1-(H30/Y30),1-(H30/L30))),0) -> 0.55063841 | AQ30: =H30/0.75 -> 234.62667 | AR30: 4 | AS30: =(AP30-MIN($AP$65:$AP$368))/(MAX($AP$65:$AP$368)-MIN($AP$65:$AP$368))*100 -> 55.063841 | AT30: =IFERROR(1-(AI30/AH30),0) -> 0 | AU30: =IFERROR(AO30/AH30,0) -> 0 | AW30: =VLOOKUP(AX30,Sup!#REF!,8,0) -> #REF! | AX30: Premium | AY30: 0 | BC30: =IF(BE30<0,BE30,0) -> 0 | BD30: =IFERROR(IF(AND(W30="",X30=""),"",IF(OR($AA$373>=$S$26,SUMIF($C:$C,C30,$W:$W)>=$S$27),S30,IF(OR($AA$373>=$R$26,SUMIF($C:$C,C30,$W:$W)>=$R$27),R30,IF(OR($AA$373>=$Q$26,SUMIF($C:$C,C30,$W:$W)>=$Q$27),Q30,IF(OR($AA$373>=$P$26,SUMIF($C:$C,C30,$W:$W)>=$P$27),P30,IF(OR($AA$373>=$O$26,SUMIF($C:$C,C30,$W:$W)>=$O$27),O30,IF(OR($AA$373>=$N$26,SUMIF($C:$C,C30,$W:$W)>=$N$27),N30,IF($AA$373>=$M$26,M30,L30)))))))*$E$13),0) | BE30: =IF(V30="",0,(V30*W30)-(BD30*W30)) -> 0 | BM30: =BM29+24 -> #REF! | BW30: EAT CLEAN | BX30: =IFERROR(W30*U30,0) -> 0 | BY30: =VLOOKUP(B30,#REF!,13,0) -> #REF! | BZ30: 322 | CA30: =VLOOKUP(B30,Pedido!$B$16:$L$292,22,0) -> #REF! | CD30: =CD29+12 -> 36 | CE30: =CD30/12 -> 3 | CF30: =CONCATENATE(CD30,CE30) -> 363 | CG30: válido
B31: 14797218847 | C31: Proteína Sabores | D31: Proteína Sabores | E31: Salted Caramel | F31: Pote | G31: 600g | H31: 192.81 | I31: 648.4896 | J31: =IFERROR(IF(T31<>"",I31/T31,IF(AND(Y31="",V31=""),"",IF(V31="",I31/Y31,I31/V31))),"") | K31: =IF(Y31="","",IFERROR(1-(Y31/I31),0)) | L31: 391.6 | M31: =P31 -> 360.272 | N31: =P31 -> 360.272 | O31: =P31 -> 360.272 | P31: 360.272 | Q31: 360.272 | R31: 360.272 | S31: 360.272 | T31: =IF(V31>0,V31,IFERROR(IF(AND(W31<>"",X31<>""),AH31/W31,Y31),"")) | U31: =IFERROR((T31*W31)/(W31+X31),"") | Y31: =IF(AND(W31="",X31=""),"",$E$13*IF(V31<>"",V31,IF(SUMIF($C:$C,C31,$W:$W)>=$S$27,S31,IF(OR($AA$373>=$R$26,SUMIF($C:$C,C31,$W:$W)>=$R$27),R31,IF(OR($AA$373>=$Q$26,SUMIF($C:$C,C31,$W:$W)>=$Q$27),Q31,IF(OR($AA$373>=$P$26,SUMIF($C:$C,C31,$W:$W)>=$P$27),P31,IF(OR($AA$373>=$O$26,SUMIF($C:$C,C31,$W:$W)>=$O$27),O31,IF(OR($AA$373>=$N$26,SUMIF($C:$C,C31,$W:$W)>=$N$27),N31,IF($AA$373>=$M$26,M31,L31))))))))) | Z31: =IF(X31>W31,-1,IF(W31=0,0,IF(U31<(H31/0.75),-1,IF(W31<=3,0,0.0001)))) -> 0 | AA31: =IFERROR(L31*W31,0) -> 0 | AB31: =IFERROR(IF(OR($AA$373>=$S$26,SUMIF($C:$C,C31,$W:$W)>=$S$27),S31,IF(OR($AA$373>=$R$26,SUMIF($C:$C,C31,$W:$W)>=$R$27),R31,IF(OR($AA$373>=$Q$26,SUMIF($C:$C,C31,$W:$W)>=$Q$27),Q31,IF(OR($AA$373>=$P$26,SUMIF($C:$C,C31,$W:$W)>=$P$27),P31,IF(OR($AA$373>=$O$26,SUMIF($C:$C,C31,$W:$W)>=$O$27),O31,IF(OR($AA$373>=$N$26,SUMIF($C:$C,C31,$W:$W)>=$N$27),N31,IF($AA$373>=$M$26,M31,L31)))))))*W31,0) -> 0 | AC31: =IFERROR(IF(V31="",0,(IF(AND(W31="",X31=""),"",IF(OR($AA$373>=$S$26,SUMIF($C:$C,C31,$W:$W)>=$S$27),S31*$E$13,IF(OR($AA$373>=$R$26,SUMIF($C:$C,C31,$W:$W)>=$R$27),R31*$E$13,IF(OR($AA$373>=$Q$26,SUMIF($C:$C,C31,$W:$W)>=$Q$27),Q31*$E$13,IF(OR($AA$373>=$P$26,SUMIF($C:$C,C31,$W:$W)>=$P$27),P31*$E$13,IF(OR($AA$373>=$O$26,SUMIF($C:$C,C31,$W:$W)>=$O$27),O31*$E$13,IF(OR($AA$373>=$N$26,SUMIF($C:$C,C31,$W:$W)>=$N$27),N31*$E$13,IF($AA$373>=$M$26,M31*$E$13,L31))))))))-V31)*W31),0) -> 0 | AD31: =IFERROR(X31*T31,0) -> 0 | AE31: =IFERROR(W31*H31,0) -> 0 | AF31: =IFERROR(1-(AE31/AB31),0) -> 0 | AG31: =IFERROR(SUM(W31:X31)*I31,0) -> 0 | AH31: =IFERROR(IF(V31>0,V31*W31,(Y31*W31)),0) -> 0 | AI31: =IFERROR(SUM(W31)*H31,0) -> 0 | AJ31: =AH31*$AJ$25 -> 0 | AK31: =AH31*AK$25 -> 0 | AL31: =AH31*AL$25 -> 0 | AM31: =SUM(AJ31:AL31) -> 0 | AN31: =AH31-AM31 -> 0 | AO31: =AN31-AI31 -> 0 | AP31: =IFERROR(IF(V31<>"",1-(H31/V31),IF(Y31<>"",1-(H31/Y31),1-(H31/L31))),0) -> 0.50763534 | AQ31: =H31/0.75 -> 257.08 | AR31: 4 | AS31: =(AP31-MIN($AP$65:$AP$368))/(MAX($AP$65:$AP$368)-MIN($AP$65:$AP$368))*100 -> 50.763534 | AT31: =IFERROR(1-(AI31/AH31),0) -> 0 | AU31: =IFERROR(AO31/AH31,0) -> 0 | AW31: =VLOOKUP(AX31,Sup!#REF!,8,0) -> #REF! | AX31: Premium | AY31: 0 | BC31: =IF(BE31<0,BE31,0) -> 0 | BD31: =IFERROR(IF(AND(W31="",X31=""),"",IF(OR($AA$373>=$S$26,SUMIF($C:$C,C31,$W:$W)>=$S$27),S31,IF(OR($AA$373>=$R$26,SUMIF($C:$C,C31,$W:$W)>=$R$27),R31,IF(OR($AA$373>=$Q$26,SUMIF($C:$C,C31,$W:$W)>=$Q$27),Q31,IF(OR($AA$373>=$P$26,SUMIF($C:$C,C31,$W:$W)>=$P$27),P31,IF(OR($AA$373>=$O$26,SUMIF($C:$C,C31,$W:$W)>=$O$27),O31,IF(OR($AA$373>=$N$26,SUMIF($C:$C,C31,$W:$W)>=$N$27),N31,IF($AA$373>=$M$26,M31,L31)))))))*$E$13),0) | BE31: =IF(V31="",0,(V31*W31)-(BD31*W31)) -> 0 | BM31: =BM29+24 -> #REF! | BW31: EAT CLEAN | BX31: =IFERROR(W31*U31,0) -> 0 | BY31: =VLOOKUP(B31,#REF!,13,0) -> #REF! | BZ31: 322 | CA31: =VLOOKUP(B31,Pedido!$B$16:$L$292,22,0) -> #N/A | CD31: =CD29+12 -> 36 | CE31: =CD31/12 -> 3 | CF31: =CONCATENATE(CD31,CE31) -> 363 | CG31: válido
B32: 14839602048 | C32: Creatina Monohidratada | D32: Creatina Monohidratada | E32: Sem sabor | F32: Pote | G32: 300 | H32: 74.16 | I32: 599.6 | J32: =IFERROR(IF(T32<>"",I32/T32,IF(AND(Y32="",V32=""),"",IF(V32="",I32/Y32,I32/V32))),"") | K32: =IF(Y32="","",IFERROR(1-(Y32/I32),0)) | L32: 460 | M32: =P32 -> 259.6 | N32: =P32 -> 259.6 | O32: =P32 -> 259.6 | P32: 259.6 | Q32: 259.6 | R32: 259.6 | S32: 259.6 | T32: =IF(V32>0,V32,IFERROR(IF(AND(W32<>"",X32<>""),AH32/W32,Y32),"")) | U32: =IFERROR((T32*W32)/(W32+X32),"") | Y32: =IF(AND(W32="",X32=""),"",$E$13*IF(V32<>"",V32,IF(SUMIF($C:$C,C32,$W:$W)>=$S$27,S32,IF(OR($AA$373>=$R$26,SUMIF($C:$C,C32,$W:$W)>=$R$27),R32,IF(OR($AA$373>=$Q$26,SUMIF($C:$C,C32,$W:$W)>=$Q$27),Q32,IF(OR($AA$373>=$P$26,SUMIF($C:$C,C32,$W:$W)>=$P$27),P32,IF(OR($AA$373>=$O$26,SUMIF($C:$C,C32,$W:$W)>=$O$27),O32,IF(OR($AA$373>=$N$26,SUMIF($C:$C,C32,$W:$W)>=$N$27),N32,IF($AA$373>=$M$26,M32,L32))))))))) | Z32: =IF(X32>W32,-1,IF(W32=0,0,IF(U32<(H32/0.75),-1,IF(W32<=3,0,0.0001)))) -> 0 | AA32: =IFERROR(L32*W32,0) -> 0 | AB32: =IFERROR(IF(OR($AA$373>=$S$26,SUMIF($C:$C,C32,$W:$W)>=$S$27),S32,IF(OR($AA$373>=$R$26,SUMIF($C:$C,C32,$W:$W)>=$R$27),R32,IF(OR($AA$373>=$Q$26,SUMIF($C:$C,C32,$W:$W)>=$Q$27),Q32,IF(OR($AA$373>=$P$26,SUMIF($C:$C,C32,$W:$W)>=$P$27),P32,IF(OR($AA$373>=$O$26,SUMIF($C:$C,C32,$W:$W)>=$O$27),O32,IF(OR($AA$373>=$N$26,SUMIF($C:$C,C32,$W:$W)>=$N$27),N32,IF($AA$373>=$M$26,M32,L32)))))))*W32,0) -> 0 | AC32: =IFERROR(IF(V32="",0,(IF(AND(W32="",X32=""),"",IF(OR($AA$373>=$S$26,SUMIF($C:$C,C32,$W:$W)>=$S$27),S32*$E$13,IF(OR($AA$373>=$R$26,SUMIF($C:$C,C32,$W:$W)>=$R$27),R32*$E$13,IF(OR($AA$373>=$Q$26,SUMIF($C:$C,C32,$W:$W)>=$Q$27),Q32*$E$13,IF(OR($AA$373>=$P$26,SUMIF($C:$C,C32,$W:$W)>=$P$27),P32*$E$13,IF(OR($AA$373>=$O$26,SUMIF($C:$C,C32,$W:$W)>=$O$27),O32*$E$13,IF(OR($AA$373>=$N$26,SUMIF($C:$C,C32,$W:$W)>=$N$27),N32*$E$13,IF($AA$373>=$M$26,M32*$E$13,L32))))))))-V32)*W32),0) -> 0 | AD32: =IFERROR(X32*T32,0) -> 0 | AE32: =IFERROR(W32*H32,0) -> 0 | AF32: =IFERROR(1-(AE32/AB32),0) -> 0 | AG32: =IFERROR(SUM(W32:X32)*I32,0) -> 0 | AH32: =IFERROR(IF(V32>0,V32*W32,(Y32*W32)),0) -> 0 | AI32: =IFERROR(SUM(W32)*H32,0) -> 0 | AJ32: =AH32*$AJ$25 -> 0 | AK32: =AH32*AK$25 -> 0 | AL32: =AH32*AL$25 -> 0 | AM32: =SUM(AJ32:AL32) -> 0 | AN32: =AH32-AM32 -> 0 | AO32: =AN32-AI32 -> 0 | AP32: =IFERROR(IF(V32<>"",1-(H32/V32),IF(Y32<>"",1-(H32/Y32),1-(H32/L32))),0) -> 0.83878261 | AQ32: =H32/0.75 -> 98.88 | AR32: 4 | AS32: =(AP32-MIN($AP$65:$AP$368))/(MAX($AP$65:$AP$368)-MIN($AP$65:$AP$368))*100 -> 83.878261 | AT32: =IFERROR(1-(AI32/AH32),0) -> 0 | AU32: =IFERROR(AO32/AH32,0) -> 0 | AW32: =VLOOKUP(AX32,Sup!#REF!,8,0) -> #REF! | AX32: Premium | AY32: 0 | BC32: =IF(BE32<0,BE32,0) -> 0 | BD32: =IFERROR(IF(AND(W32="",X32=""),"",IF(OR($AA$373>=$S$26,SUMIF($C:$C,C32,$W:$W)>=$S$27),S32,IF(OR($AA$373>=$R$26,SUMIF($C:$C,C32,$W:$W)>=$R$27),R32,IF(OR($AA$373>=$Q$26,SUMIF($C:$C,C32,$W:$W)>=$Q$27),Q32,IF(OR($AA$373>=$P$26,SUMIF($C:$C,C32,$W:$W)>=$P$27),P32,IF(OR($AA$373>=$O$26,SUMIF($C:$C,C32,$W:$W)>=$O$27),O32,IF(OR($AA$373>=$N$26,SUMIF($C:$C,C32,$W:$W)>=$N$27),N32,IF($AA$373>=$M$26,M32,L32)))))))*$E$13),0) | BE32: =IF(V32="",0,(V32*W32)-(BD32*W32)) -> 0 | BM32: =BM31+24 -> #REF! | BW32: EAT CLEAN | BX32: =IFERROR(W32*U32,0) -> 0 | BY32: =VLOOKUP(B32,#REF!,13,0) -> #REF! | BZ32: 236 | CA32: =VLOOKUP(B32,Pedido!$B$16:$L$292,22,0) -> #N/A | CD32: =CD31+12 -> 48 | CE32: =CD32/12 -> 4 | CF32: =CONCATENATE(CD32,CE32) -> 484 | CG32: válido
B33: 520554098 | C33: Creatina Eat | D33: Creatina Monohidratada | E33: Melancia com Morango | F33: Pote | G33: 210 | H33: 175.97 | I33: =119.9*4 -> 479.6 | L33: 343.6 | M33: 263.6 | N33: 263.6 | O33: 263.6 | P33: 263.6 | Q33: 263.6 | R33: 263.6 | S33: 263.6
B34: 520554099 | C34: Creatina Eat | D34: Creatina Monohidratada | E34: Blue Lemonade | F34: Pote | G34: 210 | H34: 175.97 | I34: 479.6 | L34: 343.6 | M34: 263.6 | N34: 263.6 | O34: 263.6 | P34: 263.6 | Q34: 263.6 | R34: 263.6 | S34: 263.6
B35: 520554034 | C35: Creatina Eat | D35: Creatina Monohidratada | E35: Maçã Verde | F35: Pote | G35: 210 | H35: 175.97 | I35: 479.6 | L35: 343.6 | M35: 263.6 | N35: 263.6 | O35: 263.6 | P35: 263.6 | Q35: 263.6 | R35: 263.6 | S35: 263.6
B36: 16129967737 | C36: Nutritional Yeast | D36: Nutritional Yeast | E36: - | F36: Pote | G36: 100g | H36: 34.6 | I36: 112.9 | J36: =IFERROR(IF(T36<>"",I36/T36,IF(AND(Y36="",V36=""),"",IF(V36="",I36/Y36,I36/V36))),"") | K36: =IF(Y36="","",IFERROR(1-(Y36/I36),0)) | L36: 59.8 | M36: =P36 -> 59.8 | N36: =P36 -> 59.8 | O36: =P36 -> 59.8 | P36: 59.8 | Q36: 59.8 | R36: 59.8 | S36: 59.8 | T36: =IF(V36>0,V36,IFERROR(IF(AND(W36<>"",X36<>""),AH36/W36,Y36),"")) | U36: =IFERROR((T36*W36)/(W36+X36),"") | Y36: =IF(AND(W36="",X36=""),"",$E$13*IF(V36<>"",V36,IF(SUMIF($C:$C,C36,$W:$W)>=$S$27,S36,IF(OR($AA$373>=$R$26,SUMIF($C:$C,C36,$W:$W)>=$R$27),R36,IF(OR($AA$373>=$Q$26,SUMIF($C:$C,C36,$W:$W)>=$Q$27),Q36,IF(OR($AA$373>=$P$26,SUMIF($C:$C,C36,$W:$W)>=$P$27),P36,IF(OR($AA$373>=$O$26,SUMIF($C:$C,C36,$W:$W)>=$O$27),O36,IF(OR($AA$373>=$N$26,SUMIF($C:$C,C36,$W:$W)>=$N$27),N36,IF($AA$373>=$M$26,M36,L36))))))))) | Z36: =IF(X36>W36,-1,IF(W36=0,0,IF(U36<(H36/0.75),-1,IF(W36<=3,0,0.0001)))) -> 0 | AA36: =IFERROR(L36*W36,0) -> 0 | AB36: =IFERROR(IF(OR($AA$373>=$S$26,SUMIF($C:$C,C36,$W:$W)>=$S$27),S36,IF(OR($AA$373>=$R$26,SUMIF($C:$C,C36,$W:$W)>=$R$27),R36,IF(OR($AA$373>=$Q$26,SUMIF($C:$C,C36,$W:$W)>=$Q$27),Q36,IF(OR($AA$373>=$P$26,SUMIF($C:$C,C36,$W:$W)>=$P$27),P36,IF(OR($AA$373>=$O$26,SUMIF($C:$C,C36,$W:$W)>=$O$27),O36,IF(OR($AA$373>=$N$26,SUMIF($C:$C,C36,$W:$W)>=$N$27),N36,IF($AA$373>=$M$26,M36,L36)))))))*W36,0) -> 0 | AC36: =IFERROR(IF(V36="",0,(IF(AND(W36="",X36=""),"",IF(OR($AA$373>=$S$26,SUMIF($C:$C,C36,$W:$W)>=$S$27),S36*$E$13,IF(OR($AA$373>=$R$26,SUMIF($C:$C,C36,$W:$W)>=$R$27),R36*$E$13,IF(OR($AA$373>=$Q$26,SUMIF($C:$C,C36,$W:$W)>=$Q$27),Q36*$E$13,IF(OR($AA$373>=$P$26,SUMIF($C:$C,C36,$W:$W)>=$P$27),P36*$E$13,IF(OR($AA$373>=$O$26,SUMIF($C:$C,C36,$W:$W)>=$O$27),O36*$E$13,IF(OR($AA$373>=$N$26,SUMIF($C:$C,C36,$W:$W)>=$N$27),N36*$E$13,IF($AA$373>=$M$26,M36*$E$13,L36))))))))-V36)*W36),0) -> 0 | AD36: =IFERROR(X36*T36,0) -> 0 | AE36: =IFERROR(W36*H36,0) -> 0 | AF36: =IFERROR(1-(AE36/AB36),0) -> 0 | AG36: =IFERROR(SUM(W36:X36)*I36,0) -> 0 | AH36: =IFERROR(IF(V36>0,V36*W36,(Y36*W36)),0) -> 0 | AI36: =IFERROR(SUM(W36)*H36,0) -> 0 | AJ36: =AH36*$AJ$25 -> 0 | AK36: =AH36*AK$25 -> 0 | AL36: =AH36*AL$25 -> 0 | AM36: =SUM(AJ36:AL36) -> 0 | AN36: =AH36-AM36 -> 0 | AO36: =AN36-AI36 -> 0 | AP36: =IFERROR(IF(V36<>"",1-(H36/V36),IF(Y36<>"",1-(H36/Y36),1-(H36/L36))),0) -> 0.42140468 | AQ36: =H36/0.75 -> 46.133333 | AR36: 4 | AS36: =(AP36-MIN($AP$65:$AP$368))/(MAX($AP$65:$AP$368)-MIN($AP$65:$AP$368))*100 -> 42.140468 | AT36: =IFERROR(1-(AI36/AH36),0) -> 0 | AU36: =IFERROR(AO36/AH36,0) -> 0 | AW36: =VLOOKUP(AX36,Sup!#REF!,8,0) -> #REF! | AX36: Premium | AY36: 0 | BC36: =IF(BE36<0,BE36,0) -> 0 | BD36: =IFERROR(IF(AND(W36="",X36=""),"",IF(OR($AA$373>=$S$26,SUMIF($C:$C,C36,$W:$W)>=$S$27),S36,IF(OR($AA$373>=$R$26,SUMIF($C:$C,C36,$W:$W)>=$R$27),R36,IF(OR($AA$373>=$Q$26,SUMIF($C:$C,C36,$W:$W)>=$Q$27),Q36,IF(OR($AA$373>=$P$26,SUMIF($C:$C,C36,$W:$W)>=$P$27),P36,IF(OR($AA$373>=$O$26,SUMIF($C:$C,C36,$W:$W)>=$O$27),O36,IF(OR($AA$373>=$N$26,SUMIF($C:$C,C36,$W:$W)>=$N$27),N36,IF($AA$373>=$M$26,M36,L36)))))))*$E$13),0) | BE36: =IF(V36="",0,(V36*W36)-(BD36*W36)) -> 0 | BM36: =BM32+24 -> #REF! | BW36: EAT CLEAN | BX36: =IFERROR(W36*U36,0) -> 0 | BY36: =VLOOKUP(B36,#REF!,13,0) -> #REF! | BZ36: 57 | CA36: =VLOOKUP(B36,Pedido!$B$16:$L$292,22,0) -> #N/A | CD36: =CD32+12 -> 60 | CE36: =CD36/12 -> 5 | CF36: =CONCATENATE(CD36,CE36) -> 605 | CG36: válido
B37: 0117898966827683 | C37: Barra de Proteína (display 12 unid) | D37: Display Barra de Proteína | E37: Chocolate Belga | F37: Barra | G37: 45g | H37: 24.13 | I37: 144.9 | J37: =IFERROR(IF(T37<>"",I37/T37,IF(AND(Y37="",V37=""),"",IF(V37="",I37/Y37,I37/V37))),"") | K37: =IF(Y37="","",IFERROR(1-(Y37/I37),0)) | L37: 84.9 | M37: =P37 -> 78.108 | N37: =P37 -> 78.108 | O37: =P37 -> 78.108 | P37: 78.108 | Q37: 78.108 | R37: 78.108 | S37: 78.108 | T37: =IF(V37>0,V37,IFERROR(IF(AND(W37<>"",X37<>""),AH37/W37,Y37),"")) | U37: =IFERROR((T37*W37)/(W37+X37),"") | Y37: =IF(AND(W37="",X37=""),"",$E$13*IF(V37<>"",V37,IF(SUMIF($C:$C,C37,$W:$W)>=$S$27,S37,IF(OR($AA$373>=$R$26,SUMIF($C:$C,C37,$W:$W)>=$R$27),R37,IF(OR($AA$373>=$Q$26,SUMIF($C:$C,C37,$W:$W)>=$Q$27),Q37,IF(OR($AA$373>=$P$26,SUMIF($C:$C,C37,$W:$W)>=$P$27),P37,IF(OR($AA$373>=$O$26,SUMIF($C:$C,C37,$W:$W)>=$O$27),O37,IF(OR($AA$373>=$N$26,SUMIF($C:$C,C37,$W:$W)>=$N$27),N37,IF($AA$373>=$M$26,M37,L37))))))))) | Z37: =IF(X37>W37,-1,IF(W37=0,0,IF(U37<(H37/0.75),-1,IF(W37<=3,0,0.0001)))) -> 0 | AA37: =IFERROR(L37*W37,0) -> 0 | AB37: =IFERROR(IF(OR($AA$373>=$S$26,SUMIF($C:$C,C37,$W:$W)>=$S$27),S37,IF(OR($AA$373>=$R$26,SUMIF($C:$C,C37,$W:$W)>=$R$27),R37,IF(OR($AA$373>=$Q$26,SUMIF($C:$C,C37,$W:$W)>=$Q$27),Q37,IF(OR($AA$373>=$P$26,SUMIF($C:$C,C37,$W:$W)>=$P$27),P37,IF(OR($AA$373>=$O$26,SUMIF($C:$C,C37,$W:$W)>=$O$27),O37,IF(OR($AA$373>=$N$26,SUMIF($C:$C,C37,$W:$W)>=$N$27),N37,IF($AA$373>=$M$26,M37,L37)))))))*W37,0) -> 0 | AC37: =IFERROR(IF(V37="",0,(IF(AND(W37="",X37=""),"",IF(OR($AA$373>=$S$26,SUMIF($C:$C,C37,$W:$W)>=$S$27),S37*$E$13,IF(OR($AA$373>=$R$26,SUMIF($C:$C,C37,$W:$W)>=$R$27),R37*$E$13,IF(OR($AA$373>=$Q$26,SUMIF($C:$C,C37,$W:$W)>=$Q$27),Q37*$E$13,IF(OR($AA$373>=$P$26,SUMIF($C:$C,C37,$W:$W)>=$P$27),P37*$E$13,IF(OR($AA$373>=$O$26,SUMIF($C:$C,C37,$W:$W)>=$O$27),O37*$E$13,IF(OR($AA$373>=$N$26,SUMIF($C:$C,C37,$W:$W)>=$N$27),N37*$E$13,IF($AA$373>=$M$26,M37*$E$13,L37))))))))-V37)*W37),0) -> 0 | AD37: =IFERROR(X37*T37,0) -> 0 | AE37: =IFERROR(W37*H37,0) -> 0 | AF37: =IFERROR(1-(AE37/AB37),0) -> 0 | AG37: =IFERROR(SUM(W37:X37)*I37,0) -> 0 | AH37: =IFERROR(IF(V37>0,V37*W37,(Y37*W37)),0) -> 0 | AI37: =IFERROR(SUM(W37)*H37,0) -> 0 | AJ37: =AH37*$AJ$25 -> 0 | AK37: =AH37*AK$25 -> 0 | AL37: =AH37*AL$25 -> 0 | AM37: =SUM(AJ37:AL37) -> 0 | AN37: =AH37-AM37 -> 0 | AO37: =AN37-AI37 -> 0 | AP37: =IFERROR(IF(V37<>"",1-(H37/V37),IF(Y37<>"",1-(H37/Y37),1-(H37/L37))),0) -> 0.71578327 | AQ37: =H37/0.75 -> 32.173333 | AR37: 12 | AS37: =(AP37-MIN($AP$65:$AP$368))/(MAX($AP$65:$AP$368)-MIN($AP$65:$AP$368))*100 -> 71.578327 | AT37: =IFERROR(1-(AI37/AH37),0) -> 0 | AU37: =IFERROR(AO37/AH37,0) -> 0 | AW37: =VLOOKUP(AX37,Sup!#REF!,8,0) -> #REF! | AX37: Premium | AY37: 0 | BC37: =IF(BE37<0,BE37,0) -> 0 | BD37: =IFERROR(IF(AND(W37="",X37=""),"",IF(OR($AA$373>=$S$26,SUMIF($C:$C,C37,$W:$W)>=$S$27),S37,IF(OR($AA$373>=$R$26,SUMIF($C:$C,C37,$W:$W)>=$R$27),R37,IF(OR($AA$373>=$Q$26,SUMIF($C:$C,C37,$W:$W)>=$Q$27),Q37,IF(OR($AA$373>=$P$26,SUMIF($C:$C,C37,$W:$W)>=$P$27),P37,IF(OR($AA$373>=$O$26,SUMIF($C:$C,C37,$W:$W)>=$O$27),O37,IF(OR($AA$373>=$N$26,SUMIF($C:$C,C37,$W:$W)>=$N$27),N37,IF($AA$373>=$M$26,M37,L37)))))))*$E$13),0) | BE37: =IF(V37="",0,(V37*W37)-(BD37*W37)) -> 0 | BM37: =BM36+24 -> #REF! | BW37: EAT CLEAN | BX37: =IFERROR(W37*U37,0) -> 0 | BY37: =VLOOKUP(B37,#REF!,13,0) -> #REF! | BZ37: 74 | CA37: =VLOOKUP(B37,Pedido!$B$16:$L$292,22,0) -> #N/A | CD37: =CD36+12 -> 72 | CE37: =CD37/12 -> 6 | CF37: =CONCATENATE(CD37,CE37) -> 726 | CG37: válido
B38: 17898966827782 | C38: Barra de Proteína (display 12 unid) | D38: Display Barra de Proteína | E38: Cookies & Cream | F38: Barra | G38: 45g | H38: 24.53 | I38: 144.9 | J38: =IFERROR(IF(T38<>"",I38/T38,IF(AND(Y38="",V38=""),"",IF(V38="",I38/Y38,I38/V38))),"") | K38: =IF(Y38="","",IFERROR(1-(Y38/I38),0)) | L38: 84.9 | M38: =P38 -> 78.108 | N38: =P38 -> 78.108 | O38: =P38 -> 78.108 | P38: 78.108 | Q38: 78.108 | R38: 78.108 | S38: 78.108 | T38: =IF(V38>0,V38,IFERROR(IF(AND(W38<>"",X38<>""),AH38/W38,Y38),"")) | U38: =IFERROR((T38*W38)/(W38+X38),"") | Y38: =IF(AND(W38="",X38=""),"",$E$13*IF(V38<>"",V38,IF(SUMIF($C:$C,C38,$W:$W)>=$S$27,S38,IF(OR($AA$373>=$R$26,SUMIF($C:$C,C38,$W:$W)>=$R$27),R38,IF(OR($AA$373>=$Q$26,SUMIF($C:$C,C38,$W:$W)>=$Q$27),Q38,IF(OR($AA$373>=$P$26,SUMIF($C:$C,C38,$W:$W)>=$P$27),P38,IF(OR($AA$373>=$O$26,SUMIF($C:$C,C38,$W:$W)>=$O$27),O38,IF(OR($AA$373>=$N$26,SUMIF($C:$C,C38,$W:$W)>=$N$27),N38,IF($AA$373>=$M$26,M38,L38))))))))) | Z38: =IF(X38>W38,-1,IF(W38=0,0,IF(U38<(H38/0.75),-1,IF(W38<=3,0,0.0001)))) -> 0 | AA38: =IFERROR(L38*W38,0) -> 0 | AB38: =IFERROR(IF(OR($AA$373>=$S$26,SUMIF($C:$C,C38,$W:$W)>=$S$27),S38,IF(OR($AA$373>=$R$26,SUMIF($C:$C,C38,$W:$W)>=$R$27),R38,IF(OR($AA$373>=$Q$26,SUMIF($C:$C,C38,$W:$W)>=$Q$27),Q38,IF(OR($AA$373>=$P$26,SUMIF($C:$C,C38,$W:$W)>=$P$27),P38,IF(OR($AA$373>=$O$26,SUMIF($C:$C,C38,$W:$W)>=$O$27),O38,IF(OR($AA$373>=$N$26,SUMIF($C:$C,C38,$W:$W)>=$N$27),N38,IF($AA$373>=$M$26,M38,L38)))))))*W38,0) -> 0 | AC38: =IFERROR(IF(V38="",0,(IF(AND(W38="",X38=""),"",IF(OR($AA$373>=$S$26,SUMIF($C:$C,C38,$W:$W)>=$S$27),S38*$E$13,IF(OR($AA$373>=$R$26,SUMIF($C:$C,C38,$W:$W)>=$R$27),R38*$E$13,IF(OR($AA$373>=$Q$26,SUMIF($C:$C,C38,$W:$W)>=$Q$27),Q38*$E$13,IF(OR($AA$373>=$P$26,SUMIF($C:$C,C38,$W:$W)>=$P$27),P38*$E$13,IF(OR($AA$373>=$O$26,SUMIF($C:$C,C38,$W:$W)>=$O$27),O38*$E$13,IF(OR($AA$373>=$N$26,SUMIF($C:$C,C38,$W:$W)>=$N$27),N38*$E$13,IF($AA$373>=$M$26,M38*$E$13,L38))))))))-V38)*W38),0) -> 0 | AD38: =IFERROR(X38*T38,0) -> 0 | AE38: =IFERROR(W38*H38,0) -> 0 | AF38: =IFERROR(1-(AE38/AB38),0) -> 0 | AG38: =IFERROR(SUM(W38:X38)*I38,0) -> 0 | AH38: =IFERROR(IF(V38>0,V38*W38,(Y38*W38)),0) -> 0 | AI38: =IFERROR(SUM(W38)*H38,0) -> 0 | AJ38: =AH38*$AJ$25 -> 0 | AK38: =AH38*AK$25 -> 0 | AL38: =AH38*AL$25 -> 0 | AM38: =SUM(AJ38:AL38) -> 0 | AN38: =AH38-AM38 -> 0 | AO38: =AN38-AI38 -> 0 | AP38: =IFERROR(IF(V38<>"",1-(H38/V38),IF(Y38<>"",1-(H38/Y38),1-(H38/L38))),0) -> 0.71107185 | AQ38: =H38/0.75 -> 32.706667 | AR38: 12 | AS38: =(AP38-MIN($AP$65:$AP$368))/(MAX($AP$65:$AP$368)-MIN($AP$65:$AP$368))*100 -> 71.107185 | AT38: =IFERROR(1-(AI38/AH38),0) -> 0 | AU38: =IFERROR(AO38/AH38,0) -> 0 | AW38: =VLOOKUP(AX38,Sup!#REF!,8,0) -> #REF! | AX38: Premium | AY38: 0 | BC38: =IF(BE38<0,BE38,0) -> 0 | BD38: =IFERROR(IF(AND(W38="",X38=""),"",IF(OR($AA$373>=$S$26,SUMIF($C:$C,C38,$W:$W)>=$S$27),S38,IF(OR($AA$373>=$R$26,SUMIF($C:$C,C38,$W:$W)>=$R$27),R38,IF(OR($AA$373>=$Q$26,SUMIF($C:$C,C38,$W:$W)>=$Q$27),Q38,IF(OR($AA$373>=$P$26,SUMIF($C:$C,C38,$W:$W)>=$P$27),P38,IF(OR($AA$373>=$O$26,SUMIF($C:$C,C38,$W:$W)>=$O$27),O38,IF(OR($AA$373>=$N$26,SUMIF($C:$C,C38,$W:$W)>=$N$27),N38,IF($AA$373>=$M$26,M38,L38)))))))*$E$13),0) | BE38: =IF(V38="",0,(V38*W38)-(BD38*W38)) -> 0 | BM38: =BM37+24 -> #REF! | BW38: EAT CLEAN | BX38: =IFERROR(W38*U38,0) -> 0 | BY38: =VLOOKUP(B38,#REF!,13,0) -> #REF! | BZ38: 74 | CA38: =VLOOKUP(B38,Pedido!$B$16:$L$292,22,0) -> #N/A | CD38: =CD37+12 -> 84 | CE38: =CD38/12 -> 7 | CF38: =CONCATENATE(CD38,CE38) -> 847 | CG38: válido
B39: 520349027 | C39: Barra de Proteína (display 12 unid) | D39: Display Barra de Proteína | E39: Doce de Leite | F39: Barra | G39: 45g | H39: 24.53 | I39: 144.9 | J39: =IFERROR(IF(T39<>"",I39/T39,IF(AND(Y39="",V39=""),"",IF(V39="",I39/Y39,I39/V39))),"") | K39: =IF(Y39="","",IFERROR(1-(Y39/I39),0)) | L39: 84.9 | M39: =P39 -> 78.108 | N39: =P39 -> 78.108 | O39: =P39 -> 78.108 | P39: 78.108 | Q39: 78.108 | R39: 78.108 | S39: 78.108 | T39: =IF(V39>0,V39,IFERROR(IF(AND(W39<>"",X39<>""),AH39/W39,Y39),"")) | U39: =IFERROR((T39*W39)/(W39+X39),"") | Y39: =IF(AND(W39="",X39=""),"",$E$13*IF(V39<>"",V39,IF(SUMIF($C:$C,C39,$W:$W)>=$S$27,S39,IF(OR($AA$373>=$R$26,SUMIF($C:$C,C39,$W:$W)>=$R$27),R39,IF(OR($AA$373>=$Q$26,SUMIF($C:$C,C39,$W:$W)>=$Q$27),Q39,IF(OR($AA$373>=$P$26,SUMIF($C:$C,C39,$W:$W)>=$P$27),P39,IF(OR($AA$373>=$O$26,SUMIF($C:$C,C39,$W:$W)>=$O$27),O39,IF(OR($AA$373>=$N$26,SUMIF($C:$C,C39,$W:$W)>=$N$27),N39,IF($AA$373>=$M$26,M39,L39))))))))) | Z39: =IF(X39>W39,-1,IF(W39=0,0,IF(U39<(H39/0.75),-1,IF(W39<=3,0,0.0001)))) -> 0 | AA39: =IFERROR(L39*W39,0) -> 0 | AB39: =IFERROR(IF(OR($AA$373>=$S$26,SUMIF($C:$C,C39,$W:$W)>=$S$27),S39,IF(OR($AA$373>=$R$26,SUMIF($C:$C,C39,$W:$W)>=$R$27),R39,IF(OR($AA$373>=$Q$26,SUMIF($C:$C,C39,$W:$W)>=$Q$27),Q39,IF(OR($AA$373>=$P$26,SUMIF($C:$C,C39,$W:$W)>=$P$27),P39,IF(OR($AA$373>=$O$26,SUMIF($C:$C,C39,$W:$W)>=$O$27),O39,IF(OR($AA$373>=$N$26,SUMIF($C:$C,C39,$W:$W)>=$N$27),N39,IF($AA$373>=$M$26,M39,L39)))))))*W39,0) -> 0 | AC39: =IFERROR(IF(V39="",0,(IF(AND(W39="",X39=""),"",IF(OR($AA$373>=$S$26,SUMIF($C:$C,C39,$W:$W)>=$S$27),S39*$E$13,IF(OR($AA$373>=$R$26,SUMIF($C:$C,C39,$W:$W)>=$R$27),R39*$E$13,IF(OR($AA$373>=$Q$26,SUMIF($C:$C,C39,$W:$W)>=$Q$27),Q39*$E$13,IF(OR($AA$373>=$P$26,SUMIF($C:$C,C39,$W:$W)>=$P$27),P39*$E$13,IF(OR($AA$373>=$O$26,SUMIF($C:$C,C39,$W:$W)>=$O$27),O39*$E$13,IF(OR($AA$373>=$N$26,SUMIF($C:$C,C39,$W:$W)>=$N$27),N39*$E$13,IF($AA$373>=$M$26,M39*$E$13,L39))))))))-V39)*W39),0) -> 0 | AD39: =IFERROR(X39*T39,0) -> 0 | AE39: =IFERROR(W39*H39,0) -> 0 | AF39: =IFERROR(1-(AE39/AB39),0) -> 0 | AG39: =IFERROR(SUM(W39:X39)*I39,0) -> 0 | AH39: =IFERROR(IF(V39>0,V39*W39,(Y39*W39)),0) -> 0 | AI39: =IFERROR(SUM(W39)*H39,0) -> 0 | AJ39: =AH39*$AJ$25 -> 0 | AK39: =AH39*AK$25 -> 0 | AL39: =AH39*AL$25 -> 0 | AM39: =SUM(AJ39:AL39) -> 0 | AN39: =AH39-AM39 -> 0 | AO39: =AN39-AI39 -> 0 | AP39: =IFERROR(IF(V39<>"",1-(H39/V39),IF(Y39<>"",1-(H39/Y39),1-(H39/L39))),0) -> 0.71107185 | AQ39: =H39/0.75 -> 32.706667 | AR39: 12 | AS39: =(AP39-MIN($AP$65:$AP$368))/(MAX($AP$65:$AP$368)-MIN($AP$65:$AP$368))*100 -> 71.107185 | AT39: =IFERROR(1-(AI39/AH39),0) -> 0 | AU39: =IFERROR(AO39/AH39,0) -> 0 | AW39: =VLOOKUP(AX39,Sup!#REF!,8,0) -> #REF! | AX39: Premium | AY39: 0 | BC39: =IF(BE39<0,BE39,0) -> 0 | BD39: =IFERROR(IF(AND(W39="",X39=""),"",IF(OR($AA$373>=$S$26,SUMIF($C:$C,C39,$W:$W)>=$S$27),S39,IF(OR($AA$373>=$R$26,SUMIF($C:$C,C39,$W:$W)>=$R$27),R39,IF(OR($AA$373>=$Q$26,SUMIF($C:$C,C39,$W:$W)>=$Q$27),Q39,IF(OR($AA$373>=$P$26,SUMIF($C:$C,C39,$W:$W)>=$P$27),P39,IF(OR($AA$373>=$O$26,SUMIF($C:$C,C39,$W:$W)>=$O$27),O39,IF(OR($AA$373>=$N$26,SUMIF($C:$C,C39,$W:$W)>=$N$27),N39,IF($AA$373>=$M$26,M39,L39)))))))*$E$13),0) | BE39: =IF(V39="",0,(V39*W39)-(BD39*W39)) -> 0 | BM39: =BM38+24 -> #REF! | BW39: EAT CLEAN | BX39: =IFERROR(W39*U39,0) -> 0 | BY39: =VLOOKUP(B39,#REF!,13,0) -> #REF! | BZ39: 74 | CA39: =VLOOKUP(B39,Pedido!$B$16:$L$292,22,0) -> #REF! | CD39: =CD38+12 -> 96 | CE39: =CD39/12 -> 8 | CF39: =CONCATENATE(CD39,CE39) -> 968 | CG39: válido
B40: 0117898966827669 | C40: Barra de Proteína (display 12 unid) | D40: Display Barra de Proteína | E40: Morango & Chocolate Branco | F40: Barra | G40: 45g | H40: 24.08 | I40: 144.9 | J40: =IFERROR(IF(T40<>"",I40/T40,IF(AND(Y40="",V40=""),"",IF(V40="",I40/Y40,I40/V40))),"") | K40: =IF(Y40="","",IFERROR(1-(Y40/I40),0)) | L40: 84.9 | M40: =P40 -> 78.108 | N40: =P40 -> 78.108 | O40: =P40 -> 78.108 | P40: 78.108 | Q40: 78.108 | R40: 78.108 | S40: 78.108 | T40: =IF(V40>0,V40,IFERROR(IF(AND(W40<>"",X40<>""),AH40/W40,Y40),"")) | U40: =IFERROR((T40*W40)/(W40+X40),"") | Y40: =IF(AND(W40="",X40=""),"",$E$13*IF(V40<>"",V40,IF(SUMIF($C:$C,C40,$W:$W)>=$S$27,S40,IF(OR($AA$373>=$R$26,SUMIF($C:$C,C40,$W:$W)>=$R$27),R40,IF(OR($AA$373>=$Q$26,SUMIF($C:$C,C40,$W:$W)>=$Q$27),Q40,IF(OR($AA$373>=$P$26,SUMIF($C:$C,C40,$W:$W)>=$P$27),P40,IF(OR($AA$373>=$O$26,SUMIF($C:$C,C40,$W:$W)>=$O$27),O40,IF(OR($AA$373>=$N$26,SUMIF($C:$C,C40,$W:$W)>=$N$27),N40,IF($AA$373>=$M$26,M40,L40))))))))) | Z40: =IF(X40>W40,-1,IF(W40=0,0,IF(U40<(H40/0.75),-1,IF(W40<=3,0,0.0001)))) -> 0 | AA40: =IFERROR(L40*W40,0) -> 0 | AB40: =IFERROR(IF(OR($AA$373>=$S$26,SUMIF($C:$C,C40,$W:$W)>=$S$27),S40,IF(OR($AA$373>=$R$26,SUMIF($C:$C,C40,$W:$W)>=$R$27),R40,IF(OR($AA$373>=$Q$26,SUMIF($C:$C,C40,$W:$W)>=$Q$27),Q40,IF(OR($AA$373>=$P$26,SUMIF($C:$C,C40,$W:$W)>=$P$27),P40,IF(OR($AA$373>=$O$26,SUMIF($C:$C,C40,$W:$W)>=$O$27),O40,IF(OR($AA$373>=$N$26,SUMIF($C:$C,C40,$W:$W)>=$N$27),N40,IF($AA$373>=$M$26,M40,L40)))))))*W40,0) -> 0 | AC40: =IFERROR(IF(V40="",0,(IF(AND(W40="",X40=""),"",IF(OR($AA$373>=$S$26,SUMIF($C:$C,C40,$W:$W)>=$S$27),S40*$E$13,IF(OR($AA$373>=$R$26,SUMIF($C:$C,C40,$W:$W)>=$R$27),R40*$E$13,IF(OR($AA$373>=$Q$26,SUMIF($C:$C,C40,$W:$W)>=$Q$27),Q40*$E$13,IF(OR($AA$373>=$P$26,SUMIF($C:$C,C40,$W:$W)>=$P$27),P40*$E$13,IF(OR($AA$373>=$O$26,SUMIF($C:$C,C40,$W:$W)>=$O$27),O40*$E$13,IF(OR($AA$373>=$N$26,SUMIF($C:$C,C40,$W:$W)>=$N$27),N40*$E$13,IF($AA$373>=$M$26,M40*$E$13,L40))))))))-V40)*W40),0) -> 0 | AD40: =IFERROR(X40*T40,0) -> 0 | AE40: =IFERROR(W40*H40,0) -> 0 | AF40: =IFERROR(1-(AE40/AB40),0) -> 0 | AG40: =IFERROR(SUM(W40:X40)*I40,0) -> 0 | AH40: =IFERROR(IF(V40>0,V40*W40,(Y40*W40)),0) -> 0 | AI40: =IFERROR(SUM(W40)*H40,0) -> 0 | AJ40: =AH40*$AJ$25 -> 0 | AK40: =AH40*AK$25 -> 0 | AL40: =AH40*AL$25 -> 0 | AM40: =SUM(AJ40:AL40) -> 0 | AN40: =AH40-AM40 -> 0 | AO40: =AN40-AI40 -> 0 | AP40: =IFERROR(IF(V40<>"",1-(H40/V40),IF(Y40<>"",1-(H40/Y40),1-(H40/L40))),0) -> 0.7163722 | AQ40: =H40/0.75 -> 32.106667 | AR40: 12 | AS40: =(AP40-MIN($AP$65:$AP$368))/(MAX($AP$65:$AP$368)-MIN($AP$65:$AP$368))*100 -> 71.63722 | AT40: =IFERROR(1-(AI40/AH40),0) -> 0 | AU40: =IFERROR(AO40/AH40,0) -> 0 | AW40: =VLOOKUP(AX40,Sup!#REF!,8,0) -> #REF! | AX40: Premium | AY40: 0 | BC40: =IF(BE40<0,BE40,0) -> 0 | BD40: =IFERROR(IF(AND(W40="",X40=""),"",IF(OR($AA$373>=$S$26,SUMIF($C:$C,C40,$W:$W)>=$S$27),S40,IF(OR($AA$373>=$R$26,SUMIF($C:$C,C40,$W:$W)>=$R$27),R40,IF(OR($AA$373>=$Q$26,SUMIF($C:$C,C40,$W:$W)>=$Q$27),Q40,IF(OR($AA$373>=$P$26,SUMIF($C:$C,C40,$W:$W)>=$P$27),P40,IF(OR($AA$373>=$O$26,SUMIF($C:$C,C40,$W:$W)>=$O$27),O40,IF(OR($AA$373>=$N$26,SUMIF($C:$C,C40,$W:$W)>=$N$27),N40,IF($AA$373>=$M$26,M40,L40)))))))*$E$13),0) | BE40: =IF(V40="",0,(V40*W40)-(BD40*W40)) -> 0 | BM40: =BM38+24 -> #REF! | BW40: EAT CLEAN | BX40: =IFERROR(W40*U40,0) -> 0 | BY40: =VLOOKUP(B40,#REF!,13,0) -> #REF! | BZ40: 74 | CA40: =VLOOKUP(B40,Pedido!$B$16:$L$292,22,0) -> #N/A | CD40: =CD38+12 -> 96 | CE40: =CD40/12 -> 8 | CF40: =CONCATENATE(CD40,CE40) -> 968 | CG40: válido
B41: 520349083 | C41: Barra de Proteína (display 12 unid) | D41: Display Barra de Proteína | E41: Pistache | F41: Barra | G41: 45g | H41: 24.08 | I41: 144.9 | J41: =IFERROR(IF(T41<>"",I41/T41,IF(AND(Y41="",V41=""),"",IF(V41="",I41/Y41,I41/V41))),"") | K41: =IF(Y41="","",IFERROR(1-(Y41/I41),0)) | L41: 84.9 | M41: =P41 -> 78.108 | N41: =P41 -> 78.108 | O41: =P41 -> 78.108 | P41: 78.108 | Q41: 78.108 | R41: 78.108 | S41: 78.108 | T41: =IF(V41>0,V41,IFERROR(IF(AND(W41<>"",X41<>""),AH41/W41,Y41),"")) | U41: =IFERROR((T41*W41)/(W41+X41),"") | Y41: =IF(AND(W41="",X41=""),"",$E$13*IF(V41<>"",V41,IF(SUMIF($C:$C,C41,$W:$W)>=$S$27,S41,IF(OR($AA$373>=$R$26,SUMIF($C:$C,C41,$W:$W)>=$R$27),R41,IF(OR($AA$373>=$Q$26,SUMIF($C:$C,C41,$W:$W)>=$Q$27),Q41,IF(OR($AA$373>=$P$26,SUMIF($C:$C,C41,$W:$W)>=$P$27),P41,IF(OR($AA$373>=$O$26,SUMIF($C:$C,C41,$W:$W)>=$O$27),O41,IF(OR($AA$373>=$N$26,SUMIF($C:$C,C41,$W:$W)>=$N$27),N41,IF($AA$373>=$M$26,M41,L41))))))))) | Z41: =IF(X41>W41,-1,IF(W41=0,0,IF(U41<(H41/0.75),-1,IF(W41<=3,0,0.0001)))) -> 0 | AA41: =IFERROR(L41*W41,0) -> 0 | AB41: =IFERROR(IF(OR($AA$373>=$S$26,SUMIF($C:$C,C41,$W:$W)>=$S$27),S41,IF(OR($AA$373>=$R$26,SUMIF($C:$C,C41,$W:$W)>=$R$27),R41,IF(OR($AA$373>=$Q$26,SUMIF($C:$C,C41,$W:$W)>=$Q$27),Q41,IF(OR($AA$373>=$P$26,SUMIF($C:$C,C41,$W:$W)>=$P$27),P41,IF(OR($AA$373>=$O$26,SUMIF($C:$C,C41,$W:$W)>=$O$27),O41,IF(OR($AA$373>=$N$26,SUMIF($C:$C,C41,$W:$W)>=$N$27),N41,IF($AA$373>=$M$26,M41,L41)))))))*W41,0) -> 0 | AC41: =IFERROR(IF(V41="",0,(IF(AND(W41="",X41=""),"",IF(OR($AA$373>=$S$26,SUMIF($C:$C,C41,$W:$W)>=$S$27),S41*$E$13,IF(OR($AA$373>=$R$26,SUMIF($C:$C,C41,$W:$W)>=$R$27),R41*$E$13,IF(OR($AA$373>=$Q$26,SUMIF($C:$C,C41,$W:$W)>=$Q$27),Q41*$E$13,IF(OR($AA$373>=$P$26,SUMIF($C:$C,C41,$W:$W)>=$P$27),P41*$E$13,IF(OR($AA$373>=$O$26,SUMIF($C:$C,C41,$W:$W)>=$O$27),O41*$E$13,IF(OR($AA$373>=$N$26,SUMIF($C:$C,C41,$W:$W)>=$N$27),N41*$E$13,IF($AA$373>=$M$26,M41*$E$13,L41))))))))-V41)*W41),0) -> 0 | AD41: =IFERROR(X41*T41,0) -> 0 | AE41: =IFERROR(W41*H41,0) -> 0 | AF41: =IFERROR(1-(AE41/AB41),0) -> 0 | AG41: =IFERROR(SUM(W41:X41)*I41,0) -> 0 | AH41: =IFERROR(IF(V41>0,V41*W41,(Y41*W41)),0) -> 0 | AI41: =IFERROR(SUM(W41)*H41,0) -> 0 | AJ41: =AH41*$AJ$25 -> 0 | AK41: =AH41*AK$25 -> 0 | AL41: =AH41*AL$25 -> 0 | AM41: =SUM(AJ41:AL41) -> 0 | AN41: =AH41-AM41 -> 0 | AO41: =AN41-AI41 -> 0 | AP41: =IFERROR(IF(V41<>"",1-(H41/V41),IF(Y41<>"",1-(H41/Y41),1-(H41/L41))),0) -> 0.7163722 | AQ41: =H41/0.75 -> 32.106667 | AR41: 12 | AS41: =(AP41-MIN($AP$65:$AP$368))/(MAX($AP$65:$AP$368)-MIN($AP$65:$AP$368))*100 -> 71.63722 | AT41: =IFERROR(1-(AI41/AH41),0) -> 0 | AU41: =IFERROR(AO41/AH41,0) -> 0 | AW41: =VLOOKUP(AX41,Sup!#REF!,8,0) -> #REF! | AX41: Premium | AY41: 0 | BC41: =IF(BE41<0,BE41,0) -> 0 | BD41: =IFERROR(IF(AND(W41="",X41=""),"",IF(OR($AA$373>=$S$26,SUMIF($C:$C,C41,$W:$W)>=$S$27),S41,IF(OR($AA$373>=$R$26,SUMIF($C:$C,C41,$W:$W)>=$R$27),R41,IF(OR($AA$373>=$Q$26,SUMIF($C:$C,C41,$W:$W)>=$Q$27),Q41,IF(OR($AA$373>=$P$26,SUMIF($C:$C,C41,$W:$W)>=$P$27),P41,IF(OR($AA$373>=$O$26,SUMIF($C:$C,C41,$W:$W)>=$O$27),O41,IF(OR($AA$373>=$N$26,SUMIF($C:$C,C41,$W:$W)>=$N$27),N41,IF($AA$373>=$M$26,M41,L41)))))))*$E$13),0) | BE41: =IF(V41="",0,(V41*W41)-(BD41*W41)) -> 0 | BM41: =BM39+24 -> #REF! | BW41: EAT CLEAN | BX41: =IFERROR(W41*U41,0) -> 0 | BY41: =VLOOKUP(B41,#REF!,13,0) -> #REF! | BZ41: 74 | CA41: =VLOOKUP(B41,Pedido!$B$16:$L$292,22,0) -> #REF! | CD41: =CD39+12 -> 108 | CE41: =CD41/12 -> 9 | CF41: =CONCATENATE(CD41,CE41) -> 1089 | CG41: válido
B42: 0117898966827676 | C42: Barra de Proteína (display 12 unid) | D42: Display Barra de Proteína | E42: Salted Caramel | F42: Barra | G42: 45g | H42: 22.9 | I42: 144.9 | J42: =IFERROR(IF(T42<>"",I42/T42,IF(AND(Y42="",V42=""),"",IF(V42="",I42/Y42,I42/V42))),"") | K42: =IF(Y42="","",IFERROR(1-(Y42/I42),0)) | L42: 84.9 | M42: =P42 -> 78.108 | N42: =P42 -> 78.108 | O42: =P42 -> 78.108 | P42: 78.108 | Q42: 78.108 | R42: 78.108 | S42: 78.108 | T42: =IF(V42>0,V42,IFERROR(IF(AND(W42<>"",X42<>""),AH42/W42,Y42),"")) | U42: =IFERROR((T42*W42)/(W42+X42),"") | Y42: =IF(AND(W42="",X42=""),"",$E$13*IF(V42<>"",V42,IF(SUMIF($C:$C,C42,$W:$W)>=$S$27,S42,IF(OR($AA$373>=$R$26,SUMIF($C:$C,C42,$W:$W)>=$R$27),R42,IF(OR($AA$373>=$Q$26,SUMIF($C:$C,C42,$W:$W)>=$Q$27),Q42,IF(OR($AA$373>=$P$26,SUMIF($C:$C,C42,$W:$W)>=$P$27),P42,IF(OR($AA$373>=$O$26,SUMIF($C:$C,C42,$W:$W)>=$O$27),O42,IF(OR($AA$373>=$N$26,SUMIF($C:$C,C42,$W:$W)>=$N$27),N42,IF($AA$373>=$M$26,M42,L42))))))))) | Z42: =IF(X42>W42,-1,IF(W42=0,0,IF(U42<(H42/0.75),-1,IF(W42<=3,0,0.0001)))) -> 0 | AA42: =IFERROR(L42*W42,0) -> 0 | AB42: =IFERROR(IF(OR($AA$373>=$S$26,SUMIF($C:$C,C42,$W:$W)>=$S$27),S42,IF(OR($AA$373>=$R$26,SUMIF($C:$C,C42,$W:$W)>=$R$27),R42,IF(OR($AA$373>=$Q$26,SUMIF($C:$C,C42,$W:$W)>=$Q$27),Q42,IF(OR($AA$373>=$P$26,SUMIF($C:$C,C42,$W:$W)>=$P$27),P42,IF(OR($AA$373>=$O$26,SUMIF($C:$C,C42,$W:$W)>=$O$27),O42,IF(OR($AA$373>=$N$26,SUMIF($C:$C,C42,$W:$W)>=$N$27),N42,IF($AA$373>=$M$26,M42,L42)))))))*W42,0) -> 0 | AC42: =IFERROR(IF(V42="",0,(IF(AND(W42="",X42=""),"",IF(OR($AA$373>=$S$26,SUMIF($C:$C,C42,$W:$W)>=$S$27),S42*$E$13,IF(OR($AA$373>=$R$26,SUMIF($C:$C,C42,$W:$W)>=$R$27),R42*$E$13,IF(OR($AA$373>=$Q$26,SUMIF($C:$C,C42,$W:$W)>=$Q$27),Q42*$E$13,IF(OR($AA$373>=$P$26,SUMIF($C:$C,C42,$W:$W)>=$P$27),P42*$E$13,IF(OR($AA$373>=$O$26,SUMIF($C:$C,C42,$W:$W)>=$O$27),O42*$E$13,IF(OR($AA$373>=$N$26,SUMIF($C:$C,C42,$W:$W)>=$N$27),N42*$E$13,IF($AA$373>=$M$26,M42*$E$13,L42))))))))-V42)*W42),0) -> 0 | AD42: =IFERROR(X42*T42,0) -> 0 | AE42: =IFERROR(W42*H42,0) -> 0 | AF42: =IFERROR(1-(AE42/AB42),0) -> 0 | AG42: =IFERROR(SUM(W42:X42)*I42,0) -> 0 | AH42: =IFERROR(IF(V42>0,V42*W42,(Y42*W42)),0) -> 0 | AI42: =IFERROR(SUM(W42)*H42,0) -> 0 | AJ42: =AH42*$AJ$25 -> 0 | AK42: =AH42*AK$25 -> 0 | AL42: =AH42*AL$25 -> 0 | AM42: =SUM(AJ42:AL42) -> 0 | AN42: =AH42-AM42 -> 0 | AO42: =AN42-AI42 -> 0 | AP42: =IFERROR(IF(V42<>"",1-(H42/V42),IF(Y42<>"",1-(H42/Y42),1-(H42/L42))),0) -> 0.73027091 | AQ42: =H42/0.75 -> 30.533333 | AR42: 12 | AS42: =(AP42-MIN($AP$65:$AP$368))/(MAX($AP$65:$AP$368)-MIN($AP$65:$AP$368))*100 -> 73.027091 | AT42: =IFERROR(1-(AI42/AH42),0) -> 0 | AU42: =IFERROR(AO42/AH42,0) -> 0 | AW42: =VLOOKUP(AX42,Sup!#REF!,8,0) -> #REF! | AX42: Premium | AY42: 0 | BC42: =IF(BE42<0,BE42,0) -> 0 | BD42: =IFERROR(IF(AND(W42="",X42=""),"",IF(OR($AA$373>=$S$26,SUMIF($C:$C,C42,$W:$W)>=$S$27),S42,IF(OR($AA$373>=$R$26,SUMIF($C:$C,C42,$W:$W)>=$R$27),R42,IF(OR($AA$373>=$Q$26,SUMIF($C:$C,C42,$W:$W)>=$Q$27),Q42,IF(OR($AA$373>=$P$26,SUMIF($C:$C,C42,$W:$W)>=$P$27),P42,IF(OR($AA$373>=$O$26,SUMIF($C:$C,C42,$W:$W)>=$O$27),O42,IF(OR($AA$373>=$N$26,SUMIF($C:$C,C42,$W:$W)>=$N$27),N42,IF($AA$373>=$M$26,M42,L42)))))))*$E$13),0) | BE42: =IF(V42="",0,(V42*W42)-(BD42*W42)) -> 0 | BM42: =BM40+24 -> #REF! | BW42: EAT CLEAN | BX42: =IFERROR(W42*U42,0) -> 0 | BY42: =VLOOKUP(B42,#REF!,13,0) -> #REF! | BZ42: 74 | CA42: =VLOOKUP(B42,Pedido!$B$16:$L$292,22,0) -> #N/A | CD42: =CD40+12 -> 108 | CE42: =CD42/12 -> 9 | CF42: =CONCATENATE(CD42,CE42) -> 1089 | CG42: válido
